Workbook
Name _1C: #REF!+Catalogue!$I$7:$I$13
Name _1C: 'HT Cable'!#REF!
Name _Toc531015269: Catalogue!$J$16
Name _Toc531015271: Catalogue!$K$16
Name _Toc531015272: Catalogue!$L$16
Name _Toc531015273: Catalogue!$M$16
Name _Toc531015274: Catalogue!$N$16
Name _Toc531015275: Catalogue!$J$17
Name _Toc531015277: Catalogue!$K$17
Name _Toc531015278: Catalogue!$L$17
Name _Toc531015279: Catalogue!$M$17
Name _Toc531015280: Catalogue!$N$17
Name _Toc531015281: Catalogue!$J$18
Name _Toc531015283: Catalogue!$K$18
Name _Toc531015284: Catalogue!$L$18
Name _Toc531015285: Catalogue!$M$18
Name _Toc531015286: Catalogue!$N$18
Name _Toc531015287: Catalogue!$J$19
Name _Toc531015289: Catalogue!$K$19
Name _Toc531015290: Catalogue!$L$19
Name _Toc531015291: Catalogue!$M$19
Name _Toc531015292: Catalogue!$N$19
Name _Toc531015293: Catalogue!$J$20
Name _Toc531015295: Catalogue!$K$20
Name _Toc531015296: Catalogue!$L$20
Name _Toc531015297: Catalogue!$M$20
Name _Toc531015298: Catalogue!$N$20
Name MRNO: #REF!
Name Q23P_RFQ: #REF!

Sheet HT Cable
C1: 2x800 MW ULTRA SUPER CRITICAL THERMAL POWER PROJECT, RAIGARH (PHASE-II), RAIPUR, CHHATTISGARH | AN1: Terminations
C2: ATTCHMENT 2 - 11kV_HT CABLE SIZNG
A3: SL No | B3: Description | C3: LOAD | L3: SHORT CIRCUIT CURRENT WITHSTAND CAPABILITY | P3: CABLE DATA | V3: CURRENT CARRYING CAPACITY | AE3: VOLTAGE DROP | AH3: MOTOR STARTING VOLTAGE DIP | AK3: Selected Cable Size / Phase | AL3: Total Length in meters | AM3: Remarks | AN3: Termination Kits | AO3: Joining Kits
C4: Type of feeder | D4: Rated power | F4: Rated Voltage | G4: Power factor | H4: Efficiency | I4: Rated full load current | J4: Motor starting current | K4: Motor starting power factor | L4: Short circuit current of switchboard | M4: Short circuit current withstand duration | N4: Minimum size required for Short circuit withstand capacity | O4: Installation | P4: No. of Cores | Q4: Size | R4: Current Rating of the Cable | S4: Cable resistance at 90°C | T4: Cable reactance at 50Hz | U4: Cable length | V4: DERATING FACTOR | AB4: Derated current carrying capacity | AC4: No. of Runs/Phase | AD4: Derated current > Rated current | AE4: ∆U | AF4: % | AG4: Allowable | AH4: ∆U | AI4: % | AJ4: Allowable | AQ4: AIR | AR4: 1C | AS4: 185
D5: kVA | E5: kW | F5: kV | I5: A | J5: A | L5: kA | M5: Sec | N5: Sq.mm | Q5: Sq.mm | R5: A | S5: Ohm / Ph / km | T5: Ohm / Ph / km | U5: Meters | V5: Ambient temperature (K1) | W5: Grouping factor (K2) | X5: Ground temprature (K3) | Y5: Depth of laying (K4) | Z5: Thermal resistivity of ground (K5) | AA5: Overall derating factor | AB5: A | AQ5: GROUND | AR5: 3C | AS5: 240
A6: 11kV SWITCHGEAR | AQ6: DUCT | AS6: 300
B7: 11 KV UNIT SWGR-3UA | AS7: 400
A8: 1 | B8: FD FAN-3A | C8: M | E8: 2450 | F8: 11 | G8: 0.85 | H8: 0.92 | I8: =IF(D8="",(E8/(1.732*F8*G8*H8)),(D8/(1.732*F8))) -> 164.44428 | J8: =IF(C8="M",7.2*I8,0) -> 1183.9988 | K8: =IF(C8="M",0.2,0) -> 0.2 | L8: 50 | M8: 0.16 | N8: =(L8*1000*SQRT(M8)/94) -> 212.76596 | O8: AIR | P8: 3C | Q8: 240 | R8: 387 | S8: 0.162 | T8: 0.088 | U8: 475 | V8: 0.89 | W8: 0.73 | X8: NA | Y8: 0 | Z8: 0 | AA8: 0.6497 | AB8: =R8*AA8 -> 251.4339 | AC8: =ROUNDUP(((I8)/AB8),0) -> 1 | AD8: =IF(AB8*AC8>=I8,"YES","NO") -> YES | AE8: =IF(C8="M",(SQRT(3)*I8*(U8/1000)*((S8/AC8)*G8+(T8/AC8)*SIN(ACOS(G8)))),(SQRT(3)*I8*(U8/1000)*((S8/AC8)*G8+(T8/AC8)*SIN(ACOS(G8))))) -> 24.901473 | AF8: =(AE8/(F8*1000))*100 -> 0.22637703 | AG8: =IF(C8="I",IF(AF8<=2,"YES","NO"),IF(AF8<=3,"YES","NO")) -> YES | AH8: =IF(C8="M",(SQRT(3)*J8*(U8/1000)*((S8/AC8)*K8+(T8/AC8)*SIN(ACOS(K8)))),"NA") -> 115.55025 | AI8: =IF(C8="M",(AH8/(F8*1000))*100,"NA") -> 1.0504568 | AJ8: =IF(C8="M",IF(AI8<=10,"YES","NO"),"NA") -> YES | AK8: =IF(C8="M",IF(AND(Q8>=N8,AD8="YES",AG8="YES",AJ8="YES"),CONCATENATE(AC8,"R X ",F8,"kV X ",P8," X ",Q8," Sqmm"),"Cable size is not correct"),IF(AND(Q8>=N8,AD8="YES",AG8="YES",AJ8="NA"),CONCATENATE(AC8,"R X ",F8,"kV X ",P8," X ",Q8," Sqmm"),"Cable size is not correct")) -> 1R X 11kV X 3C X 240 Sqmm | AL8: =IF(P8="1C",3*U8*AC8,U8*AC8) -> 475 | AN8: =AC8*2 -> 2 | AS8: 500
A9: 2 | B9: PA Fan 3A | C9: M | E9: 3900 | F9: 11 | G9: 0.88 | H9: 0.95 | I9: =IF(D9="",(E9/(1.732*F9*G9*H9)),(D9/(1.732*F9))) -> 244.85995 | J9: =IF(C9="M",7.2*I9,0) -> 1762.9916 | K9: =IF(C9="M",0.2,0) -> 0.2 | L9: 50 | M9: 0.16 | N9: =(L9*1000*SQRT(M9)/94) -> 212.76596 | O9: AIR | P9: 3C | Q9: 300 | R9: 441 | S9: 0.13 | T9: 0.086 | U9: 500 | V9: 0.89 | W9: 0.73 | X9: NA | Y9: 0 | Z9: 0 | AA9: 0.6497 | AB9: =R9*AA9 -> 286.5177 | AC9: =ROUNDUP(((I9)/AB9),0) -> 1 | AD9: =IF(AB9*AC9>=I9,"YES","NO") -> YES | AE9: =IF(C9="M",(SQRT(3)*I9*(U9/1000)*((S9/AC9)*G9+(T9/AC9)*SIN(ACOS(G9)))),(SQRT(3)*I9*(U9/1000)*((S9/AC9)*G9+(T9/AC9)*SIN(ACOS(G9))))) -> 32.921049 | AF9: =(AE9/(F9*1000))*100 -> 0.29928226 | AG9: =IF(C9="I",IF(AF9<=2,"YES","NO"),IF(AF9<=3,"YES","NO")) -> YES | AH9: =IF(C9="M",(SQRT(3)*J9*(U9/1000)*((S9/AC9)*K9+(T9/AC9)*SIN(ACOS(K9)))),"NA") -> 168.34821 | AI9: =IF(C9="M",(AH9/(F9*1000))*100,"NA") -> 1.5304383 | AJ9: =IF(C9="M",IF(AI9<=10,"YES","NO"),"NA") -> YES | AK9: =IF(C9="M",IF(AND(Q9>=N9,AD9="YES",AG9="YES",AJ9="YES"),CONCATENATE(AC9,"R X ",F9,"kV X ",P9," X ",Q9," Sqmm"),"Cable size is not correct"),IF(AND(Q9>=N9,AD9="YES",AG9="YES",AJ9="NA"),CONCATENATE(AC9,"R X ",F9,"kV X ",P9," X ",Q9," Sqmm"),"Cable size is not correct")) -> 1R X 11kV X 3C X 300 Sqmm | AL9: =IF(P9="1C",3*U9*AC9,U9*AC9) -> 500 | AN9: =AC9*2 -> 2 | AS9: 630
A10: 3 | B10: CW Pump #1 | C10: M | E10: 4325 | F10: 11 | G10: 0.77 | H10: 0.945 | I10: =IF(D10="",(E10/(1.732*F10*G10*H10)),(D10/(1.732*F10))) -> 311.97731 | J10: =IF(C10="M",7.2*I10,0) -> 2246.2366 | K10: =IF(C10="M",0.2,0) -> 0.2 | L10: 50 | M10: 0.16 | N10: =(L10*1000*SQRT(M10)/94) -> 212.76596 | O10: AIR | P10: 1C | Q10: 300 | R10: 387 | S10: 0.162 | T10: 0.088 | U10: 750 | V10: 0.89 | W10: 0.73 | X10: NA | Y10: 0 | Z10: 0 | AA10: 0.6497 | AB10: =R10*AA10 -> 251.4339 | AC10: 2 | AD10: =IF(AB10*AC10>=I10,"YES","NO") -> YES | AE10: =IF(C10="M",(SQRT(3)*I10*(U10/1000)*((S10/AC10)*G10+(T10/AC10)*SIN(ACOS(G10)))),(SQRT(3)*I10*(U10/1000)*((S10/AC10)*G10+(T10/AC10)*SIN(ACOS(G10))))) -> 36.654249 | AF10: =(AE10/(F10*1000))*100 -> 0.33322045 | AG10: =IF(C10="I",IF(AF10<=2,"YES","NO"),IF(AF10<=3,"YES","NO")) -> YES | AH10: =IF(C10="M",(SQRT(3)*J10*(U10/1000)*((S10/AC10)*K10+(T10/AC10)*SIN(ACOS(K10)))),"NA") -> 173.06641 | AI10: =IF(C10="M",(AH10/(F10*1000))*100,"NA") -> 1.573331 | AJ10: =IF(C10="M",IF(AI10<=10,"YES","NO"),"NA") -> YES | AK10: =IF(C10="M",IF(AND(Q10>=N10,AD10="YES",AG10="YES",AJ10="YES"),CONCATENATE(AC10,"R X ",F10,"kV X ",P10," X ",Q10," Sqmm"),"Cable size is not correct"),IF(AND(Q10>=N10,AD10="YES",AG10="YES",AJ10="NA"),CONCATENATE(AC10,"R X ",F10,"kV X ",P10," X ",Q10," Sqmm"),"Cable size is not correct")) -> 2R X 11kV X 1C X 300 Sqmm | AL10: =IF(P10="1C",3*U10*AC10,U10*AC10) -> 4500 | AN10: =AC10*2 -> 4
A11: 4 | B11: ID FAN #3A | C11: M | E11: 11350 | F11: 11 | G11: 0.85 | H11: 0.97 | I11: =IF(D11="",(E11/(1.732*F11*G11*H11)),(D11/(1.732*F11))) -> 722.54455 | J11: =IF(C11="M",7.2*I11,0) -> 5202.3207 | K11: =IF(C11="M",0.2,0) -> 0.2 | L11: 50 | M11: 0.16 | N11: =(L11*1000*SQRT(M11)/94) -> 212.76596 | O11: AIR | P11: 1C | Q11: 300 | R11: 575 | S11: 0.1018 | T11: 0.0937 | U11: 410 | V11: 0.89 | W11: 0.78 | X11: NA | Y11: 0 | Z11: 0 | AA11: 0.6942 | AB11: =R11*AA11 -> 399.165 | AC11: =ROUNDUP(((I11)/AB11),0) -> 2 | AD11: =IF(AB11*AC11>=I11,"YES","NO") -> YES | AE11: =IF(C11="M",(SQRT(3)*I11*(U11/1000)*((S11/AC11)*G11+(T11/AC11)*SIN(ACOS(G11)))),(SQRT(3)*I11*(U11/1000)*((S11/AC11)*G11+(T11/AC11)*SIN(ACOS(G11))))) -> 34.863031 | AF11: =(AE11/(F11*1000))*100 -> 0.31693664 | AG11: =IF(C11="I",IF(AF11<=2,"YES","NO"),IF(AF11<=3,"YES","NO")) -> YES | AH11: =IF(C11="M",(SQRT(3)*J11*(U11/1000)*((S11/AC11)*K11+(T11/AC11)*SIN(ACOS(K11)))),"NA") -> 207.19355 | AI11: =IF(C11="M",(AH11/(F11*1000))*100,"NA") -> 1.8835777 | AJ11: =IF(C11="M",IF(AI11<=10,"YES","NO"),"NA") -> YES | AK11: =IF(C11="M",IF(AND(Q11>=N11,AD11="YES",AG11="YES",AJ11="YES"),CONCATENATE(AC11,"R X ",F11,"kV X ",P11," X ",Q11," Sqmm"),"Cable size is not correct"),IF(AND(Q11>=N11,AD11="YES",AG11="YES",AJ11="NA"),CONCATENATE(AC11,"R X ",F11,"kV X ",P11," X ",Q11," Sqmm"),"Cable size is not correct")) -> 2R X 11kV X 1C X 300 Sqmm | AL11: =IF(P11="1C",3*U11*AC11,U11*AC11) -> 2460 | AN11: =AC11*2 -> 4
A12: 5 | B12: MDBFP | C12: M | E12: 13000 | F12: 11 | G12: 0.85 | H12: 0.92 | I12: =IF(D12="",(E12/(1.732*F12*G12*H12)),(D12/(1.732*F12))) -> 872.56146 | J12: =IF(C12="M",7.2*I12,0) -> 6282.4425 | K12: =IF(C12="M",0.2,0) -> 0.2 | L12: 50 | M12: 0.16 | N12: =(L12*1000*SQRT(M12)/94) -> 212.76596 | O12: AIR | P12: 1C | Q12: 400 | R12: 575 | S12: 0.1018 | T12: 0.0937 | U12: 85 | V12: 0.89 | W12: 0.78 | X12: NA | Y12: 0 | Z12: 0 | AA12: 0.6942 | AB12: =R12*AA12 -> 399.165 | AC12: 3 | AD12: =IF(AB12*AC12>=I12,"YES","NO") -> YES | AE12: =IF(C12="M",(SQRT(3)*I12*(U12/1000)*((S12/AC12)*G12+(T12/AC12)*SIN(ACOS(G12)))),(SQRT(3)*I12*(U12/1000)*((S12/AC12)*G12+(T12/AC12)*SIN(ACOS(G12))))) -> 5.8188927 | AF12: =(AE12/(F12*1000))*100 -> 0.052899024 | AG12: =IF(C12="I",IF(AF12<=2,"YES","NO"),IF(AF12<=3,"YES","NO")) -> YES | AH12: =IF(C12="M",(SQRT(3)*J12*(U12/1000)*((S12/AC12)*K12+(T12/AC12)*SIN(ACOS(K12)))),"NA") -> 34.582106 | AI12: =IF(C12="M",(AH12/(F12*1000))*100,"NA") -> 0.31438279 | AJ12: =IF(C12="M",IF(AI12<=10,"YES","NO"),"NA") -> YES | AK12: =IF(C12="M",IF(AND(Q12>=N12,AD12="YES",AG12="YES",AJ12="YES"),CONCATENATE(AC12,"R X ",F12,"kV X ",P12," X ",Q12," Sqmm"),"Cable size is not correct"),IF(AND(Q12>=N12,AD12="YES",AG12="YES",AJ12="NA"),CONCATENATE(AC12,"R X ",F12,"kV X ",P12," X ",Q12," Sqmm"),"Cable size is not correct")) -> 3R X 11kV X 1C X 400 Sqmm | AL12: =IF(P12="1C",3*U12*AC12,U12*AC12) -> 765 | AN12: =AC12*2 -> 6
A13: 6 | B13: HVAC Transformer Feeder | C13: F | D13: 3000 | F13: 11 | G13: 0.85 | H13: 0.92 | I13: =IF(D13="",(E13/(1.732*F13*G13*H13)),(D13/(1.732*F13))) -> 157.46378 | J13: =IF(C13="M",7.2*I13,0) -> 0 | K13: =IF(C13="M",0.2,0) -> 0 | L13: 50 | M13: 0.16 | N13: =(L13*1000*SQRT(M13)/94) -> 212.76596 | O13: AIR | P13: 3C | Q13: 240 | R13: 387 | S13: 0.162 | T13: 0.088 | U13: 460 | V13: 0.89 | W13: 0.73 | X13: NA | Y13: 0 | Z13: 0 | AA13: 0.6497 | AB13: =R13*AA13 -> 251.4339 | AC13: =ROUNDUP(((I13)/AB13),0) -> 1 | AD13: =IF(AB13*AC13>=I13,"YES","NO") -> YES | AE13: =IF(C13="M",(SQRT(3)*I13*(U13/1000)*((S13/AC13)*G13+(T13/AC13)*SIN(ACOS(G13)))),(SQRT(3)*I13*(U13/1000)*((S13/AC13)*G13+(T13/AC13)*SIN(ACOS(G13))))) -> 23.091449 | AF13: =(AE13/(F13*1000))*100 -> 0.20992226 | AG13: =IF(C13="I",IF(AF13<=2,"YES","NO"),IF(AF13<=3,"YES","NO")) -> YES | AH13: =IF(C13="M",(SQRT(3)*J13*(U13/1000)*((S13/AC13)*K13+(T13/AC13)*SIN(ACOS(K13)))),"NA") -> NA | AI13: =IF(C13="M",(AH13/(F13*1000))*100,"NA") -> NA | AJ13: =IF(C13="M",IF(AI13<=10,"YES","NO"),"NA") -> NA | AK13: =IF(C13="M",IF(AND(Q13>=N13,AD13="YES",AG13="YES",AJ13="YES"),CONCATENATE(AC13,"R X ",F13,"kV X ",P13," X ",Q13," Sqmm"),"Cable size is not correct"),IF(AND(Q13>=N13,AD13="YES",AG13="YES",AJ13="NA"),CONCATENATE(AC13,"R X ",F13,"kV X ",P13," X ",Q13," Sqmm"),"Cable size is not correct")) -> 1R X 11kV X 3C X 240 Sqmm | AL13: =IF(P13="1C",3*U13*AC13,U13*AC13) -> 460 | AN13: =AC13*2 -> 2
A14: 7 | B14: Turbine Tower Service Transformer Feeder | C14: F | D14: 2500 | F14: 11 | G14: 0.85 | H14: 0.92 | I14: =IF(D14="",(E14/(1.732*F14*G14*H14)),(D14/(1.732*F14))) -> 131.21982 | J14: =IF(C14="M",7.2*I14,0) -> 0 | K14: =IF(C14="M",0.2,0) -> 0 | L14: 50 | M14: 0.16 | N14: =(L14*1000*SQRT(M14)/94) -> 212.76596 | O14: AIR | P14: 3C | Q14: 240 | R14: 387 | S14: 0.162 | T14: 0.088 | U14: 470 | V14: 0.89 | W14: 0.73 | X14: NA | Y14: 0 | Z14: 0 | AA14: 0.6497 | AB14: =R14*AA14 -> 251.4339 | AC14: =ROUNDUP(((I14)/AB14),0) -> 1 | AD14: =IF(AB14*AC14>=I14,"YES","NO") -> YES | AE14: =IF(C14="M",(SQRT(3)*I14*(U14/1000)*((S14/AC14)*G14+(T14/AC14)*SIN(ACOS(G14)))),(SQRT(3)*I14*(U14/1000)*((S14/AC14)*G14+(T14/AC14)*SIN(ACOS(G14))))) -> 19.661198 | AF14: =(AE14/(F14*1000))*100 -> 0.17873816 | AG14: =IF(C14="I",IF(AF14<=2,"YES","NO"),IF(AF14<=3,"YES","NO")) -> YES | AH14: =IF(C14="M",(SQRT(3)*J14*(U14/1000)*((S14/AC14)*K14+(T14/AC14)*SIN(ACOS(K14)))),"NA") -> NA | AI14: =IF(C14="M",(AH14/(F14*1000))*100,"NA") -> NA | AJ14: =IF(C14="M",IF(AI14<=10,"YES","NO"),"NA") -> NA | AK14: =IF(C14="M",IF(AND(Q14>=N14,AD14="YES",AG14="YES",AJ14="YES"),CONCATENATE(AC14,"R X ",F14,"kV X ",P14," X ",Q14," Sqmm"),"Cable size is not correct"),IF(AND(Q14>=N14,AD14="YES",AG14="YES",AJ14="NA"),CONCATENATE(AC14,"R X ",F14,"kV X ",P14," X ",Q14," Sqmm"),"Cable size is not correct")) -> 1R X 11kV X 3C X 240 Sqmm | AL14: =IF(P14="1C",3*U14*AC14,U14*AC14) -> 470 | AN14: =AC14*2 -> 2
A15: 8 | B15: Boiler Service Transformer Feeder | C15: F | D15: 3150 | F15: 11 | G15: 0.85 | H15: 0.92 | I15: =IF(D15="",(E15/(1.732*F15*G15*H15)),(D15/(1.732*F15))) -> 165.33697 | J15: =IF(C15="M",7.2*I15,0) -> 0 | K15: =IF(C15="M",0.2,0) -> 0 | L15: 50 | M15: 0.16 | N15: =(L15*1000*SQRT(M15)/94) -> 212.76596 | O15: AIR | P15: 3C | Q15: 240 | R15: 387 | S15: 0.162 | T15: 0.088 | U15: 460 | V15: 0.89 | W15: 0.73 | X15: NA | Y15: 0 | Z15: 0 | AA15: 0.6497 | AB15: =R15*AA15 -> 251.4339 | AC15: =ROUNDUP(((I15)/AB15),0) -> 1 | AD15: =IF(AB15*AC15>=I15,"YES","NO") -> YES | AE15: =IF(C15="M",(SQRT(3)*I15*(U15/1000)*((S15/AC15)*G15+(T15/AC15)*SIN(ACOS(G15)))),(SQRT(3)*I15*(U15/1000)*((S15/AC15)*G15+(T15/AC15)*SIN(ACOS(G15))))) -> 24.246022 | AF15: =(AE15/(F15*1000))*100 -> 0.22041838 | AG15: =IF(C15="I",IF(AF15<=2,"YES","NO"),IF(AF15<=3,"YES","NO")) -> YES | AH15: =IF(C15="M",(SQRT(3)*J15*(U15/1000)*((S15/AC15)*K15+(T15/AC15)*SIN(ACOS(K15)))),"NA") -> NA | AI15: =IF(C15="M",(AH15/(F15*1000))*100,"NA") -> NA | AJ15: =IF(C15="M",IF(AI15<=10,"YES","NO"),"NA") -> NA | AK15: =IF(C15="M",IF(AND(Q15>=N15,AD15="YES",AG15="YES",AJ15="YES"),CONCATENATE(AC15,"R X ",F15,"kV X ",P15," X ",Q15," Sqmm"),"Cable size is not correct"),IF(AND(Q15>=N15,AD15="YES",AG15="YES",AJ15="NA"),CONCATENATE(AC15,"R X ",F15,"kV X ",P15," X ",Q15," Sqmm"),"Cable size is not correct")) -> 1R X 11kV X 3C X 240 Sqmm | AL15: =IF(P15="1C",3*U15*AC15,U15*AC15) -> 460 | AN15: =AC15*2 -> 2
A16: 9 | B16: ESP Service Transformer Feeder-1 | C16: F | D16: 2500 | F16: 11 | G16: 0.85 | H16: 0.92 | I16: =IF(D16="",(E16/(1.732*F16*G16*H16)),(D16/(1.732*F16))) -> 131.21982 | J16: =IF(C16="M",7.2*I16,0) -> 0 | K16: =IF(C16="M",0.2,0) -> 0 | L16: 50 | M16: 0.16 | N16: =(L16*1000*SQRT(M16)/94) -> 212.76596 | O16: AIR | P16: 3C | Q16: 240 | R16: 387 | S16: 0.162 | T16: 0.088 | U16: 490 | V16: 0.89 | W16: 0.73 | X16: NA | Y16: 0 | Z16: 0 | AA16: 0.6497 | AB16: =R16*AA16 -> 251.4339 | AC16: =ROUNDUP(((I16)/AB16),0) -> 1 | AD16: =IF(AB16*AC16>=I16,"YES","NO") -> YES | AE16: =IF(C16="M",(SQRT(3)*I16*(U16/1000)*((S16/AC16)*G16+(T16/AC16)*SIN(ACOS(G16)))),(SQRT(3)*I16*(U16/1000)*((S16/AC16)*G16+(T16/AC16)*SIN(ACOS(G16))))) -> 20.497844 | AF16: =(AE16/(F16*1000))*100 -> 0.18634404 | AG16: =IF(C16="I",IF(AF16<=2,"YES","NO"),IF(AF16<=3,"YES","NO")) -> YES | AH16: =IF(C16="M",(SQRT(3)*J16*(U16/1000)*((S16/AC16)*K16+(T16/AC16)*SIN(ACOS(K16)))),"NA") -> NA | AI16: =IF(C16="M",(AH16/(F16*1000))*100,"NA") -> NA | AJ16: =IF(C16="M",IF(AI16<=10,"YES","NO"),"NA") -> NA | AK16: =IF(C16="M",IF(AND(Q16>=N16,AD16="YES",AG16="YES",AJ16="YES"),CONCATENATE(AC16,"R X ",F16,"kV X ",P16," X ",Q16," Sqmm"),"Cable size is not correct"),IF(AND(Q16>=N16,AD16="YES",AG16="YES",AJ16="NA"),CONCATENATE(AC16,"R X ",F16,"kV X ",P16," X ",Q16," Sqmm"),"Cable size is not correct")) -> 1R X 11kV X 3C X 240 Sqmm | AL16: =IF(P16="1C",3*U16*AC16,U16*AC16) -> 490 | AN16: =AC16*2 -> 2
A17: 10 | B17: ESP Service Transformer Feeder-2 | C17: F | D17: 2500 | F17: 11 | G17: 0.85 | H17: 0.92 | I17: =IF(D17="",(E17/(1.732*F17*G17*H17)),(D17/(1.732*F17))) -> 131.21982 | J17: =IF(C17="M",7.2*I17,0) -> 0 | K17: =IF(C17="M",0.2,0) -> 0 | L17: 50 | M17: 0.16 | N17: =(L17*1000*SQRT(M17)/94) -> 212.76596 | O17: AIR | P17: 3C | Q17: 240 | R17: 387 | S17: 0.162 | T17: 0.088 | U17: 490 | V17: 0.89 | W17: 0.73 | X17: NA | Y17: 0 | Z17: 0 | AA17: 0.6497 | AB17: =R17*AA17 -> 251.4339 | AC17: =ROUNDUP(((I17)/AB17),0) -> 1 | AD17: =IF(AB17*AC17>=I17,"YES","NO") -> YES | AE17: =IF(C17="M",(SQRT(3)*I17*(U17/1000)*((S17/AC17)*G17+(T17/AC17)*SIN(ACOS(G17)))),(SQRT(3)*I17*(U17/1000)*((S17/AC17)*G17+(T17/AC17)*SIN(ACOS(G17))))) -> 20.497844 | AF17: =(AE17/(F17*1000))*100 -> 0.18634404 | AG17: =IF(C17="I",IF(AF17<=2,"YES","NO"),IF(AF17<=3,"YES","NO")) -> YES | AH17: =IF(C17="M",(SQRT(3)*J17*(U17/1000)*((S17/AC17)*K17+(T17/AC17)*SIN(ACOS(K17)))),"NA") -> NA | AI17: =IF(C17="M",(AH17/(F17*1000))*100,"NA") -> NA | AJ17: =IF(C17="M",IF(AI17<=10,"YES","NO"),"NA") -> NA | AK17: =IF(C17="M",IF(AND(Q17>=N17,AD17="YES",AG17="YES",AJ17="YES"),CONCATENATE(AC17,"R X ",F17,"kV X ",P17," X ",Q17," Sqmm"),"Cable size is not correct"),IF(AND(Q17>=N17,AD17="YES",AG17="YES",AJ17="NA"),CONCATENATE(AC17,"R X ",F17,"kV X ",P17," X ",Q17," Sqmm"),"Cable size is not correct")) -> 1R X 11kV X 3C X 240 Sqmm | AL17: =IF(P17="1C",3*U17*AC17,U17*AC17) -> 490 | AN17: =AC17*2 -> 2
A18: 11 | B18: ESP Service Transformer Feeder-3 | C18: F | D18: 2500 | F18: 11 | G18: 0.85 | H18: 0.92 | I18: =IF(D18="",(E18/(1.732*F18*G18*H18)),(D18/(1.732*F18))) -> 131.21982 | J18: =IF(C18="M",7.2*I18,0) -> 0 | K18: =IF(C18="M",0.2,0) -> 0 | L18: 50 | M18: 0.16 | N18: =(L18*1000*SQRT(M18)/94) -> 212.76596 | O18: AIR | P18: 3C | Q18: 240 | R18: 387 | S18: 0.162 | T18: 0.088 | U18: 490 | V18: 0.89 | W18: 0.73 | X18: NA | Y18: 0 | Z18: 0 | AA18: 0.6497 | AB18: =R18*AA18 -> 251.4339 | AC18: =ROUNDUP(((I18)/AB18),0) -> 1 | AD18: =IF(AB18*AC18>=I18,"YES","NO") -> YES | AE18: =IF(C18="M",(SQRT(3)*I18*(U18/1000)*((S18/AC18)*G18+(T18/AC18)*SIN(ACOS(G18)))),(SQRT(3)*I18*(U18/1000)*((S18/AC18)*G18+(T18/AC18)*SIN(ACOS(G18))))) -> 20.497844 | AF18: =(AE18/(F18*1000))*100 -> 0.18634404 | AG18: =IF(C18="I",IF(AF18<=2,"YES","NO"),IF(AF18<=3,"YES","NO")) -> YES | AH18: =IF(C18="M",(SQRT(3)*J18*(U18/1000)*((S18/AC18)*K18+(T18/AC18)*SIN(ACOS(K18)))),"NA") -> NA | AI18: =IF(C18="M",(AH18/(F18*1000))*100,"NA") -> NA | AJ18: =IF(C18="M",IF(AI18<=10,"YES","NO"),"NA") -> NA | AK18: =IF(C18="M",IF(AND(Q18>=N18,AD18="YES",AG18="YES",AJ18="YES"),CONCATENATE(AC18,"R X ",F18,"kV X ",P18," X ",Q18," Sqmm"),"Cable size is not correct"),IF(AND(Q18>=N18,AD18="YES",AG18="YES",AJ18="NA"),CONCATENATE(AC18,"R X ",F18,"kV X ",P18," X ",Q18," Sqmm"),"Cable size is not correct")) -> 1R X 11kV X 3C X 240 Sqmm | AL18: =IF(P18="1C",3*U18*AC18,U18*AC18) -> 490 | AN18: =AC18*2 -> 2
A19: 12 | B19: Cooling Tower Transformer Feeder-2A | C19: F | D19: 3000 | F19: 11 | G19: 0.85 | H19: 0.92 | I19: =IF(D19="",(E19/(1.732*F19*G19*H19)),(D19/(1.732*F19))) -> 157.46378 | J19: =IF(C19="M",7.2*I19,0) -> 0 | K19: =IF(C19="M",0.2,0) -> 0 | L19: 50 | M19: 0.16 | N19: =(L19*1000*SQRT(M19)/94) -> 212.76596 | O19: AIR | P19: 3C | Q19: 240 | R19: 387 | S19: 0.162 | T19: 0.088 | U19: 1100 | V19: 0.89 | W19: 0.73 | X19: NA | Y19: 0 | Z19: 0 | AA19: 0.6497 | AB19: =R19*AA19 -> 251.4339 | AC19: =ROUNDUP(((I19)/AB19),0) -> 1 | AD19: =IF(AB19*AC19>=I19,"YES","NO") -> YES | AE19: =IF(C19="M",(SQRT(3)*I19*(U19/1000)*((S19/AC19)*G19+(T19/AC19)*SIN(ACOS(G19)))),(SQRT(3)*I19*(U19/1000)*((S19/AC19)*G19+(T19/AC19)*SIN(ACOS(G19))))) -> 55.218683 | AF19: =(AE19/(F19*1000))*100 -> 0.50198802 | AG19: =IF(C19="I",IF(AF19<=2,"YES","NO"),IF(AF19<=3,"YES","NO")) -> YES | AH19: =IF(C19="M",(SQRT(3)*J19*(U19/1000)*((S19/AC19)*K19+(T19/AC19)*SIN(ACOS(K19)))),"NA") -> NA | AI19: =IF(C19="M",(AH19/(F19*1000))*100,"NA") -> NA | AJ19: =IF(C19="M",IF(AI19<=10,"YES","NO"),"NA") -> NA | AK19: =IF(C19="M",IF(AND(Q19>=N19,AD19="YES",AG19="YES",AJ19="YES"),CONCATENATE(AC19,"R X ",F19,"kV X ",P19," X ",Q19," Sqmm"),"Cable size is not correct"),IF(AND(Q19>=N19,AD19="YES",AG19="YES",AJ19="NA"),CONCATENATE(AC19,"R X ",F19,"kV X ",P19," X ",Q19," Sqmm"),"Cable size is not correct")) -> 1R X 11kV X 3C X 240 Sqmm | AL19: =IF(P19="1C",3*U19*AC19,U19*AC19) -> 1100 | AN19: =AC19*2 -> 2
A20: 13 | B20: UAT Auxiliary Transformer Feeder | C20: F | D20: 20000 | F20: 11 | G20: 0.85 | H20: 0.92 | I20: =IF(D20="",(E20/(1.732*F20*G20*H20)),(D20/(1.732*F20))) -> 1049.7586 | J20: =IF(C20="M",7.2*I20,0) -> 0 | K20: =IF(C20="M",0.2,0) -> 0 | L20: 50 | M20: 0.16 | N20: =(L20*1000*SQRT(M20)/94) -> 212.76596 | O20: AIR | P20: 1C | Q20: 400 | R20: 575 | S20: 0.1018 | T20: 0.0937 | U20: 120 | V20: 0.89 | W20: 0.78 | X20: NA | Y20: 0 | Z20: 0 | AA20: 0.6942 | AB20: =R20*AA20 -> 399.165 | AC20: =ROUNDUP(((I20)/AB20),0) -> 3 | AD20: =IF(AB20*AC20>=I20,"YES","NO") -> YES | AE20: =IF(C20="M",(SQRT(3)*I20*(U20/1000)*((S20/AC20)*G20+(T20/AC20)*SIN(ACOS(G20)))),(SQRT(3)*I20*(U20/1000)*((S20/AC20)*G20+(T20/AC20)*SIN(ACOS(G20))))) -> 9.8831654 | AF20: =(AE20/(F20*1000))*100 -> 0.089846958 | AG20: =IF(C20="I",IF(AF20<=2,"YES","NO"),IF(AF20<=3,"YES","NO")) -> YES | AH20: =IF(C20="M",(SQRT(3)*J20*(U20/1000)*((S20/AC20)*K20+(T20/AC20)*SIN(ACOS(K20)))),"NA") -> NA | AI20: =IF(C20="M",(AH20/(F20*1000))*100,"NA") -> NA | AJ20: =IF(C20="M",IF(AI20<=10,"YES","NO"),"NA") -> NA | AK20: =IF(C20="M",IF(AND(Q20>=N20,AD20="YES",AG20="YES",AJ20="YES"),CONCATENATE(AC20,"R X ",F20,"kV X ",P20," X ",Q20," Sqmm"),"Cable size is not correct"),IF(AND(Q20>=N20,AD20="YES",AG20="YES",AJ20="NA"),CONCATENATE(AC20,"R X ",F20,"kV X ",P20," X ",Q20," Sqmm"),"Cable size is not correct")) -> 3R X 11kV X 1C X 400 Sqmm | AL20: =IF(P20="1C",3*U20*AC20,U20*AC20) -> 1080 | AN20: =AC20*2 -> 6
B22: 11 KV UNIT SWGR-3UB | AN22: =AC22*2 -> 0
A23: 1 | B23: FD FAN-3B | C23: M | E23: 2450 | F23: 11 | G23: 0.85 | H23: 0.92 | I23: =IF(D23="",(E23/(1.732*F23*G23*H23)),(D23/(1.732*F23))) -> 164.44428 | J23: =IF(C23="M",7.2*I23,0) -> 1183.9988 | K23: =IF(C23="M",0.2,0) -> 0.2 | L23: 50 | M23: 0.16 | N23: =(L23*1000*SQRT(M23)/94) -> 212.76596 | O23: AIR | P23: 3C | Q23: 240 | R23: 387 | S23: 0.162 | T23: 0.088 | U23: 475 | V23: 0.89 | W23: 0.73 | X23: NA | Y23: 0 | Z23: 0 | AA23: 0.6497 | AB23: =R23*AA23 -> 251.4339 | AC23: =ROUNDUP(((I23)/AB23),0) -> 1 | AD23: =IF(AB23*AC23>=I23,"YES","NO") -> YES | AE23: =IF(C23="M",(SQRT(3)*I23*(U23/1000)*((S23/AC23)*G23+(T23/AC23)*SIN(ACOS(G23)))),(SQRT(3)*I23*(U23/1000)*((S23/AC23)*G23+(T23/AC23)*SIN(ACOS(G23))))) -> 24.901473 | AF23: =(AE23/(F23*1000))*100 -> 0.22637703 | AG23: =IF(C23="I",IF(AF23<=2,"YES","NO"),IF(AF23<=3,"YES","NO")) -> YES | AH23: =IF(C23="M",(SQRT(3)*J23*(U23/1000)*((S23/AC23)*K23+(T23/AC23)*SIN(ACOS(K23)))),"NA") -> 115.55025 | AI23: =IF(C23="M",(AH23/(F23*1000))*100,"NA") -> 1.0504568 | AJ23: =IF(C23="M",IF(AI23<=10,"YES","NO"),"NA") -> YES | AK23: =IF(C23="M",IF(AND(Q23>=N23,AD23="YES",AG23="YES",AJ23="YES"),CONCATENATE(AC23,"R X ",F23,"kV X ",P23," X ",Q23," Sqmm"),"Cable size is not correct"),IF(AND(Q23>=N23,AD23="YES",AG23="YES",AJ23="NA"),CONCATENATE(AC23,"R X ",F23,"kV X ",P23," X ",Q23," Sqmm"),"Cable size is not correct")) -> 1R X 11kV X 3C X 240 Sqmm | AL23: =IF(P23="1C",3*U23*AC23,U23*AC23) -> 475 | AN23: =AC23*2 -> 2
A24: 2 | B24: PA Fan 3B | C24: M | E24: 3900 | F24: 11 | G24: 0.88 | H24: 0.95 | I24: =IF(D24="",(E24/(1.732*F24*G24*H24)),(D24/(1.732*F24))) -> 244.85995 | J24: =IF(C24="M",7.2*I24,0) -> 1762.9916 | K24: =IF(C24="M",0.2,0) -> 0.2 | L24: 50 | M24: 0.16 | N24: =(L24*1000*SQRT(M24)/94) -> 212.76596 | O24: AIR | P24: 3C | Q24: 300 | R24: 441 | S24: 0.13 | T24: 0.086 | U24: 500 | V24: 0.89 | W24: 0.73 | X24: NA | Y24: 0 | Z24: 0 | AA24: 0.6497 | AB24: =R24*AA24 -> 286.5177 | AC24: =ROUNDUP(((I24)/AB24),0) -> 1 | AD24: =IF(AB24*AC24>=I24,"YES","NO") -> YES | AE24: =IF(C24="M",(SQRT(3)*I24*(U24/1000)*((S24/AC24)*G24+(T24/AC24)*SIN(ACOS(G24)))),(SQRT(3)*I24*(U24/1000)*((S24/AC24)*G24+(T24/AC24)*SIN(ACOS(G24))))) -> 32.921049 | AF24: =(AE24/(F24*1000))*100 -> 0.29928226 | AG24: =IF(C24="I",IF(AF24<=2,"YES","NO"),IF(AF24<=3,"YES","NO")) -> YES | AH24: =IF(C24="M",(SQRT(3)*J24*(U24/1000)*((S24/AC24)*K24+(T24/AC24)*SIN(ACOS(K24)))),"NA") -> 168.34821 | AI24: =IF(C24="M",(AH24/(F24*1000))*100,"NA") -> 1.5304383 | AJ24: =IF(C24="M",IF(AI24<=10,"YES","NO"),"NA") -> YES | AK24: =IF(C24="M",IF(AND(Q24>=N24,AD24="YES",AG24="YES",AJ24="YES"),CONCATENATE(AC24,"R X ",F24,"kV X ",P24," X ",Q24," Sqmm"),"Cable size is not correct"),IF(AND(Q24>=N24,AD24="YES",AG24="YES",AJ24="NA"),CONCATENATE(AC24,"R X ",F24,"kV X ",P24," X ",Q24," Sqmm"),"Cable size is not correct")) -> 1R X 11kV X 3C X 300 Sqmm | AL24: =IF(P24="1C",3*U24*AC24,U24*AC24) -> 500 | AN24: =AC24*2 -> 2
A25: 3 | B25: CW Pump #2 | C25: M | E25: 4325 | F25: 11 | G25: 0.77 | H25: 0.945 | I25: =IF(D25="",(E25/(1.732*F25*G25*H25)),(D25/(1.732*F25))) -> 311.97731 | J25: =IF(C25="M",7.2*I25,0) -> 2246.2366 | K25: =IF(C25="M",0.2,0) -> 0.2 | L25: 50 | M25: 0.16 | N25: =(L25*1000*SQRT(M25)/94) -> 212.76596 | O25: AIR | P25: 1C | Q25: 300 | R25: 387 | S25: 0.162 | T25: 0.088 | U25: 750 | V25: 0.89 | W25: 0.73 | X25: NA | Y25: 0 | Z25: 0 | AA25: 0.6497 | AB25: =R25*AA25 -> 251.4339 | AC25: 2 | AD25: =IF(AB25*AC25>=I25,"YES","NO") -> YES | AE25: =IF(C25="M",(SQRT(3)*I25*(U25/1000)*((S25/AC25)*G25+(T25/AC25)*SIN(ACOS(G25)))),(SQRT(3)*I25*(U25/1000)*((S25/AC25)*G25+(T25/AC25)*SIN(ACOS(G25))))) -> 36.654249 | AF25: =(AE25/(F25*1000))*100 -> 0.33322045 | AG25: =IF(C25="I",IF(AF25<=2,"YES","NO"),IF(AF25<=3,"YES","NO")) -> YES | AH25: =IF(C25="M",(SQRT(3)*J25*(U25/1000)*((S25/AC25)*K25+(T25/AC25)*SIN(ACOS(K25)))),"NA") -> 173.06641 | AI25: =IF(C25="M",(AH25/(F25*1000))*100,"NA") -> 1.573331 | AJ25: =IF(C25="M",IF(AI25<=10,"YES","NO"),"NA") -> YES | AK25: =IF(C25="M",IF(AND(Q25>=N25,AD25="YES",AG25="YES",AJ25="YES"),CONCATENATE(AC25,"R X ",F25,"kV X ",P25," X ",Q25," Sqmm"),"Cable size is not correct"),IF(AND(Q25>=N25,AD25="YES",AG25="YES",AJ25="NA"),CONCATENATE(AC25,"R X ",F25,"kV X ",P25," X ",Q25," Sqmm"),"Cable size is not correct")) -> 2R X 11kV X 1C X 300 Sqmm | AL25: =IF(P25="1C",3*U25*AC25,U25*AC25) -> 4500 | AN25: =AC25*2 -> 4
A26: 4 | B26: ID FAN #3B | C26: M | E26: 11350 | F26: 11 | G26: 0.85 | H26: 0.97 | I26: =IF(D26="",(E26/(1.732*F26*G26*H26)),(D26/(1.732*F26))) -> 722.54455 | J26: =IF(C26="M",7.2*I26,0) -> 5202.3207 | K26: =IF(C26="M",0.2,0) -> 0.2 | L26: 50 | M26: 0.16 | N26: =(L26*1000*SQRT(M26)/94) -> 212.76596 | O26: AIR | P26: 1C | Q26: 400 | R26: 575 | S26: 0.1018 | T26: 0.0937 | U26: 410 | V26: 0.89 | W26: 0.78 | X26: NA | Y26: 0 | Z26: 0 | AA26: 0.6942 | AB26: =R26*AA26 -> 399.165 | AC26: =ROUNDUP(((I26)/AB26),0) -> 2 | AD26: =IF(AB26*AC26>=I26,"YES","NO") -> YES | AE26: =IF(C26="M",(SQRT(3)*I26*(U26/1000)*((S26/AC26)*G26+(T26/AC26)*SIN(ACOS(G26)))),(SQRT(3)*I26*(U26/1000)*((S26/AC26)*G26+(T26/AC26)*SIN(ACOS(G26))))) -> 34.863031 | AF26: =(AE26/(F26*1000))*100 -> 0.31693664 | AG26: =IF(C26="I",IF(AF26<=2,"YES","NO"),IF(AF26<=3,"YES","NO")) -> YES | AH26: =IF(C26="M",(SQRT(3)*J26*(U26/1000)*((S26/AC26)*K26+(T26/AC26)*SIN(ACOS(K26)))),"NA") -> 207.19355 | AI26: =IF(C26="M",(AH26/(F26*1000))*100,"NA") -> 1.8835777 | AJ26: =IF(C26="M",IF(AI26<=10,"YES","NO"),"NA") -> YES | AK26: =IF(C26="M",IF(AND(Q26>=N26,AD26="YES",AG26="YES",AJ26="YES"),CONCATENATE(AC26,"R X ",F26,"kV X ",P26," X ",Q26," Sqmm"),"Cable size is not correct"),IF(AND(Q26>=N26,AD26="YES",AG26="YES",AJ26="NA"),CONCATENATE(AC26,"R X ",F26,"kV X ",P26," X ",Q26," Sqmm"),"Cable size is not correct")) -> 2R X 11kV X 1C X 400 Sqmm | AL26: =IF(P26="1C",3*U26*AC26,U26*AC26) -> 2460 | AN26: =AC26*2 -> 4
A27: 5 | B27: UAT Auxiliary Transformer Feeder | C27: F | D27: 20000 | F27: 11 | G27: 0.83 | H27: 0.93 | I27: =IF(D27="",(E27/(1.732*F27*G27*H27)),(D27/(1.732*F27))) -> 1049.7586 | J27: =IF(C27="M",7.2*I27,0) -> 0 | K27: =IF(C27="M",0.2,0) -> 0 | L27: 50 | M27: 0.16 | N27: =(L27*1000*SQRT(M27)/94) -> 212.76596 | O27: AIR | P27: 1C | Q27: 400 | R27: 575 | S27: 0.1018 | T27: 0.0937 | U27: 120 | V27: 0.89 | W27: 0.78 | X27: NA | Y27: 0 | Z27: 0 | AA27: 0.6942 | AB27: =R27*AA27 -> 399.165 | AC27: =ROUNDUP(((I27)/AB27),0) -> 3 | AD27: =IF(AB27*AC27>=I27,"YES","NO") -> YES | AE27: =IF(C27="M",(SQRT(3)*I27*(U27/1000)*((S27/AC27)*G27+(T27/AC27)*SIN(ACOS(G27)))),(SQRT(3)*I27*(U27/1000)*((S27/AC27)*G27+(T27/AC27)*SIN(ACOS(G27))))) -> 9.9462139 | AF27: =(AE27/(F27*1000))*100 -> 0.090420127 | AG27: =IF(C27="I",IF(AF27<=2,"YES","NO"),IF(AF27<=3,"YES","NO")) -> YES | AH27: =IF(C27="M",(SQRT(3)*J27*(U27/1000)*((S27/AC27)*K27+(T27/AC27)*SIN(ACOS(K27)))),"NA") -> NA | AI27: =IF(C27="M",(AH27/(F27*1000))*100,"NA") -> NA | AJ27: =IF(C27="M",IF(AI27<=10,"YES","NO"),"NA") -> NA | AK27: =IF(C27="M",IF(AND(Q27>=N27,AD27="YES",AG27="YES",AJ27="YES"),CONCATENATE(AC27,"R X ",F27,"kV X ",P27," X ",Q27," Sqmm"),"Cable size is not correct"),IF(AND(Q27>=N27,AD27="YES",AG27="YES",AJ27="NA"),CONCATENATE(AC27,"R X ",F27,"kV X ",P27," X ",Q27," Sqmm"),"Cable size is not correct")) -> 3R X 11kV X 1C X 400 Sqmm | AL27: =IF(P27="1C",3*U27*AC27,U27*AC27) -> 1080 | AN27: =AC27*2 -> 6
A28: 6 | B28: HVAC Service Transformer Feeder | C28: F | D28: 3000 | F28: 11 | G28: 0.85 | H28: 0.92 | I28: =IF(D28="",(E28/(1.732*F28*G28*H28)),(D28/(1.732*F28))) -> 157.46378 | J28: =IF(C28="M",7.2*I28,0) -> 0 | K28: =IF(C28="M",0.2,0) -> 0 | L28: 50 | M28: 0.16 | N28: =(L28*1000*SQRT(M28)/94) -> 212.76596 | O28: AIR | P28: 3C | Q28: 240 | R28: 387 | S28: 0.162 | T28: 0.088 | U28: 460 | V28: 0.89 | W28: 0.73 | X28: NA | Y28: 0 | Z28: 0 | AA28: 0.6497 | AB28: =R28*AA28 -> 251.4339 | AC28: =ROUNDUP(((I28)/AB28),0) -> 1 | AD28: =IF(AB28*AC28>=I28,"YES","NO") -> YES | AE28: =IF(C28="M",(SQRT(3)*I28*(U28/1000)*((S28/AC28)*G28+(T28/AC28)*SIN(ACOS(G28)))),(SQRT(3)*I28*(U28/1000)*((S28/AC28)*G28+(T28/AC28)*SIN(ACOS(G28))))) -> 23.091449 | AF28: =(AE28/(F28*1000))*100 -> 0.20992226 | AG28: =IF(C28="I",IF(AF28<=2,"YES","NO"),IF(AF28<=3,"YES","NO")) -> YES | AH28: =IF(C28="M",(SQRT(3)*J28*(U28/1000)*((S28/AC28)*K28+(T28/AC28)*SIN(ACOS(K28)))),"NA") -> NA | AI28: =IF(C28="M",(AH28/(F28*1000))*100,"NA") -> NA | AJ28: =IF(C28="M",IF(AI28<=10,"YES","NO"),"NA") -> NA | AK28: =IF(C28="M",IF(AND(Q28>=N28,AD28="YES",AG28="YES",AJ28="YES"),CONCATENATE(AC28,"R X ",F28,"kV X ",P28," X ",Q28," Sqmm"),"Cable size is not correct"),IF(AND(Q28>=N28,AD28="YES",AG28="YES",AJ28="NA"),CONCATENATE(AC28,"R X ",F28,"kV X ",P28," X ",Q28," Sqmm"),"Cable size is not correct")) -> 1R X 11kV X 3C X 240 Sqmm | AL28: =IF(P28="1C",3*U28*AC28,U28*AC28) -> 460
A29: 7 | B29: Turbine Tower Service Transformer Feeder | C29: F | D29: 2500 | F29: 11 | G29: 0.85 | H29: 0.92 | I29: =IF(D29="",(E29/(1.732*F29*G29*H29)),(D29/(1.732*F29))) -> 131.21982 | J29: =IF(C29="M",7.2*I29,0) -> 0 | K29: =IF(C29="M",0.2,0) -> 0 | L29: 50 | M29: 0.16 | N29: =(L29*1000*SQRT(M29)/94) -> 212.76596 | O29: AIR | P29: 3C | Q29: 240 | R29: 387 | S29: 0.162 | T29: 0.088 | U29: 470 | V29: 0.89 | W29: 0.73 | X29: NA | Y29: 0 | Z29: 0 | AA29: 0.6497 | AB29: =R29*AA29 -> 251.4339 | AC29: =ROUNDUP(((I29)/AB29),0) -> 1 | AD29: =IF(AB29*AC29>=I29,"YES","NO") -> YES | AE29: =IF(C29="M",(SQRT(3)*I29*(U29/1000)*((S29/AC29)*G29+(T29/AC29)*SIN(ACOS(G29)))),(SQRT(3)*I29*(U29/1000)*((S29/AC29)*G29+(T29/AC29)*SIN(ACOS(G29))))) -> 19.661198 | AF29: =(AE29/(F29*1000))*100 -> 0.17873816 | AG29: =IF(C29="I",IF(AF29<=2,"YES","NO"),IF(AF29<=3,"YES","NO")) -> YES | AH29: =IF(C29="M",(SQRT(3)*J29*(U29/1000)*((S29/AC29)*K29+(T29/AC29)*SIN(ACOS(K29)))),"NA") -> NA | AI29: =IF(C29="M",(AH29/(F29*1000))*100,"NA") -> NA | AJ29: =IF(C29="M",IF(AI29<=10,"YES","NO"),"NA") -> NA | AK29: =IF(C29="M",IF(AND(Q29>=N29,AD29="YES",AG29="YES",AJ29="YES"),CONCATENATE(AC29,"R X ",F29,"kV X ",P29," X ",Q29," Sqmm"),"Cable size is not correct"),IF(AND(Q29>=N29,AD29="YES",AG29="YES",AJ29="NA"),CONCATENATE(AC29,"R X ",F29,"kV X ",P29," X ",Q29," Sqmm"),"Cable size is not correct")) -> 1R X 11kV X 3C X 240 Sqmm | AL29: =IF(P29="1C",3*U29*AC29,U29*AC29) -> 470 | AN29: =AC29*2 -> 2
A30: 8 | B30: Boiler Service Transformer Feeder | C30: F | D30: 3000 | F30: 11 | G30: 0.85 | H30: 0.92 | I30: =IF(D30="",(E30/(1.732*F30*G30*H30)),(D30/(1.732*F30))) -> 157.46378 | J30: =IF(C30="M",7.2*I30,0) -> 0 | K30: =IF(C30="M",0.2,0) -> 0 | L30: 50 | M30: 0.16 | N30: =(L30*1000*SQRT(M30)/94) -> 212.76596 | O30: AIR | P30: 3C | Q30: 240 | R30: 387 | S30: 0.162 | T30: 0.088 | U30: 460 | V30: 0.89 | W30: 0.73 | X30: NA | Y30: 0 | Z30: 0 | AA30: 0.6497 | AB30: =R30*AA30 -> 251.4339 | AC30: =ROUNDUP(((I30)/AB30),0) -> 1 | AD30: =IF(AB30*AC30>=I30,"YES","NO") -> YES | AE30: =IF(C30="M",(SQRT(3)*I30*(U30/1000)*((S30/AC30)*G30+(T30/AC30)*SIN(ACOS(G30)))),(SQRT(3)*I30*(U30/1000)*((S30/AC30)*G30+(T30/AC30)*SIN(ACOS(G30))))) -> 23.091449 | AF30: =(AE30/(F30*1000))*100 -> 0.20992226 | AG30: =IF(C30="I",IF(AF30<=2,"YES","NO"),IF(AF30<=3,"YES","NO")) -> YES | AH30: =IF(C30="M",(SQRT(3)*J30*(U30/1000)*((S30/AC30)*K30+(T30/AC30)*SIN(ACOS(K30)))),"NA") -> NA | AI30: =IF(C30="M",(AH30/(F30*1000))*100,"NA") -> NA | AJ30: =IF(C30="M",IF(AI30<=10,"YES","NO"),"NA") -> NA | AK30: =IF(C30="M",IF(AND(Q30>=N30,AD30="YES",AG30="YES",AJ30="YES"),CONCATENATE(AC30,"R X ",F30,"kV X ",P30," X ",Q30," Sqmm"),"Cable size is not correct"),IF(AND(Q30>=N30,AD30="YES",AG30="YES",AJ30="NA"),CONCATENATE(AC30,"R X ",F30,"kV X ",P30," X ",Q30," Sqmm"),"Cable size is not correct")) -> 1R X 11kV X 3C X 240 Sqmm | AL30: =IF(P30="1C",3*U30*AC30,U30*AC30) -> 460 | AN30: =AC30*2 -> 2
A31: 9 | B31: ESP Service Transformer Feeder-4 | C31: F | D31: 2500 | F31: 11 | G31: 0.85 | H31: 0.92 | I31: =IF(D31="",(E31/(1.732*F31*G31*H31)),(D31/(1.732*F31))) -> 131.21982 | J31: =IF(C31="M",7.2*I31,0) -> 0 | K31: =IF(C31="M",0.2,0) -> 0 | L31: 50 | M31: 0.16 | N31: =(L31*1000*SQRT(M31)/94) -> 212.76596 | O31: AIR | P31: 3C | Q31: 240 | R31: 387 | S31: 0.162 | T31: 0.088 | U31: 490 | V31: 0.89 | W31: 0.73 | X31: NA | Y31: 0 | Z31: 0 | AA31: 0.6497 | AB31: =R31*AA31 -> 251.4339 | AC31: =ROUNDUP(((I31)/AB31),0) -> 1 | AD31: =IF(AB31*AC31>=I31,"YES","NO") -> YES | AE31: =IF(C31="M",(SQRT(3)*I31*(U31/1000)*((S31/AC31)*G31+(T31/AC31)*SIN(ACOS(G31)))),(SQRT(3)*I31*(U31/1000)*((S31/AC31)*G31+(T31/AC31)*SIN(ACOS(G31))))) -> 20.497844 | AF31: =(AE31/(F31*1000))*100 -> 0.18634404 | AG31: =IF(C31="I",IF(AF31<=2,"YES","NO"),IF(AF31<=3,"YES","NO")) -> YES | AH31: =IF(C31="M",(SQRT(3)*J31*(U31/1000)*((S31/AC31)*K31+(T31/AC31)*SIN(ACOS(K31)))),"NA") -> NA | AI31: =IF(C31="M",(AH31/(F31*1000))*100,"NA") -> NA | AJ31: =IF(C31="M",IF(AI31<=10,"YES","NO"),"NA") -> NA | AK31: =IF(C31="M",IF(AND(Q31>=N31,AD31="YES",AG31="YES",AJ31="YES"),CONCATENATE(AC31,"R X ",F31,"kV X ",P31," X ",Q31," Sqmm"),"Cable size is not correct"),IF(AND(Q31>=N31,AD31="YES",AG31="YES",AJ31="NA"),CONCATENATE(AC31,"R X ",F31,"kV X ",P31," X ",Q31," Sqmm"),"Cable size is not correct")) -> 1R X 11kV X 3C X 240 Sqmm | AL31: =IF(P31="1C",3*U31*AC31,U31*AC31) -> 490 | AN31: =AC31*2 -> 2
A32: 10 | B32: ESP Service Transformer Feeder-5 | C32: F | D32: 2500 | F32: 11 | G32: 0.85 | H32: 0.92 | I32: =IF(D32="",(E32/(1.732*F32*G32*H32)),(D32/(1.732*F32))) -> 131.21982 | J32: =IF(C32="M",7.2*I32,0) -> 0 | K32: =IF(C32="M",0.2,0) -> 0 | L32: 50 | M32: 0.16 | N32: =(L32*1000*SQRT(M32)/94) -> 212.76596 | O32: AIR | P32: 3C | Q32: 240 | R32: 387 | S32: 0.162 | T32: 0.088 | U32: 490 | V32: 0.89 | W32: 0.73 | X32: NA | Y32: 0 | Z32: 0 | AA32: 0.6497 | AB32: =R32*AA32 -> 251.4339 | AC32: =ROUNDUP(((I32)/AB32),0) -> 1 | AD32: =IF(AB32*AC32>=I32,"YES","NO") -> YES | AE32: =IF(C32="M",(SQRT(3)*I32*(U32/1000)*((S32/AC32)*G32+(T32/AC32)*SIN(ACOS(G32)))),(SQRT(3)*I32*(U32/1000)*((S32/AC32)*G32+(T32/AC32)*SIN(ACOS(G32))))) -> 20.497844 | AF32: =(AE32/(F32*1000))*100 -> 0.18634404 | AG32: =IF(C32="I",IF(AF32<=2,"YES","NO"),IF(AF32<=3,"YES","NO")) -> YES | AH32: =IF(C32="M",(SQRT(3)*J32*(U32/1000)*((S32/AC32)*K32+(T32/AC32)*SIN(ACOS(K32)))),"NA") -> NA | AI32: =IF(C32="M",(AH32/(F32*1000))*100,"NA") -> NA | AJ32: =IF(C32="M",IF(AI32<=10,"YES","NO"),"NA") -> NA | AK32: =IF(C32="M",IF(AND(Q32>=N32,AD32="YES",AG32="YES",AJ32="YES"),CONCATENATE(AC32,"R X ",F32,"kV X ",P32," X ",Q32," Sqmm"),"Cable size is not correct"),IF(AND(Q32>=N32,AD32="YES",AG32="YES",AJ32="NA"),CONCATENATE(AC32,"R X ",F32,"kV X ",P32," X ",Q32," Sqmm"),"Cable size is not correct")) -> 1R X 11kV X 3C X 240 Sqmm | AL32: =IF(P32="1C",3*U32*AC32,U32*AC32) -> 490 | AN32: =AC32*2 -> 2
A33: 11 | B33: ESP Service Transformer Feeder-6 | C33: F | D33: 2500 | F33: 11 | G33: 0.85 | H33: 0.92 | I33: =IF(D33="",(E33/(1.732*F33*G33*H33)),(D33/(1.732*F33))) -> 131.21982 | J33: =IF(C33="M",7.2*I33,0) -> 0 | K33: =IF(C33="M",0.2,0) -> 0 | L33: 50 | M33: 0.16 | N33: =(L33*1000*SQRT(M33)/94) -> 212.76596 | O33: AIR | P33: 3C | Q33: 240 | R33: 387 | S33: 0.162 | T33: 0.088 | U33: 490 | V33: 0.89 | W33: 0.73 | X33: NA | Y33: 0 | Z33: 0 | AA33: 0.6497 | AB33: =R33*AA33 -> 251.4339 | AC33: =ROUNDUP(((I33)/AB33),0) -> 1 | AD33: =IF(AB33*AC33>=I33,"YES","NO") -> YES | AE33: =IF(C33="M",(SQRT(3)*I33*(U33/1000)*((S33/AC33)*G33+(T33/AC33)*SIN(ACOS(G33)))),(SQRT(3)*I33*(U33/1000)*((S33/AC33)*G33+(T33/AC33)*SIN(ACOS(G33))))) -> 20.497844 | AF33: =(AE33/(F33*1000))*100 -> 0.18634404 | AG33: =IF(C33="I",IF(AF33<=2,"YES","NO"),IF(AF33<=3,"YES","NO")) -> YES | AH33: =IF(C33="M",(SQRT(3)*J33*(U33/1000)*((S33/AC33)*K33+(T33/AC33)*SIN(ACOS(K33)))),"NA") -> NA | AI33: =IF(C33="M",(AH33/(F33*1000))*100,"NA") -> NA | AJ33: =IF(C33="M",IF(AI33<=10,"YES","NO"),"NA") -> NA | AK33: =IF(C33="M",IF(AND(Q33>=N33,AD33="YES",AG33="YES",AJ33="YES"),CONCATENATE(AC33,"R X ",F33,"kV X ",P33," X ",Q33," Sqmm"),"Cable size is not correct"),IF(AND(Q33>=N33,AD33="YES",AG33="YES",AJ33="NA"),CONCATENATE(AC33,"R X ",F33,"kV X ",P33," X ",Q33," Sqmm"),"Cable size is not correct")) -> 1R X 11kV X 3C X 240 Sqmm | AL33: =IF(P33="1C",3*U33*AC33,U33*AC33) -> 490 | AN33: =AC33*2 -> 2
A34: 12 | B34: Cooling Tower Transformer Feeder-2B | C34: F | D34: 3000 | F34: 11 | G34: 0.85 | H34: 0.92 | I34: =IF(D34="",(E34/(1.732*F34*G34*H34)),(D34/(1.732*F34))) -> 157.46378 | J34: =IF(C34="M",7.2*I34,0) -> 0 | K34: =IF(C34="M",0.2,0) -> 0 | L34: 50 | M34: 0.16 | N34: =(L34*1000*SQRT(M34)/94) -> 212.76596 | O34: AIR | P34: 3C | Q34: 240 | R34: 387 | S34: 0.162 | T34: 0.088 | U34: 1100 | V34: 0.89 | W34: 0.73 | X34: NA | Y34: 0 | Z34: 0 | AA34: 0.6497 | AB34: =R34*AA34 -> 251.4339 | AC34: =ROUNDUP(((I34)/AB34),0) -> 1 | AD34: =IF(AB34*AC34>=I34,"YES","NO") -> YES | AE34: =IF(C34="M",(SQRT(3)*I34*(U34/1000)*((S34/AC34)*G34+(T34/AC34)*SIN(ACOS(G34)))),(SQRT(3)*I34*(U34/1000)*((S34/AC34)*G34+(T34/AC34)*SIN(ACOS(G34))))) -> 55.218683 | AF34: =(AE34/(F34*1000))*100 -> 0.50198802 | AG34: =IF(C34="I",IF(AF34<=2,"YES","NO"),IF(AF34<=3,"YES","NO")) -> YES | AH34: =IF(C34="M",(SQRT(3)*J34*(U34/1000)*((S34/AC34)*K34+(T34/AC34)*SIN(ACOS(K34)))),"NA") -> NA | AI34: =IF(C34="M",(AH34/(F34*1000))*100,"NA") -> NA | AJ34: =IF(C34="M",IF(AI34<=10,"YES","NO"),"NA") -> NA | AK34: =IF(C34="M",IF(AND(Q34>=N34,AD34="YES",AG34="YES",AJ34="YES"),CONCATENATE(AC34,"R X ",F34,"kV X ",P34," X ",Q34," Sqmm"),"Cable size is not correct"),IF(AND(Q34>=N34,AD34="YES",AG34="YES",AJ34="NA"),CONCATENATE(AC34,"R X ",F34,"kV X ",P34," X ",Q34," Sqmm"),"Cable size is not correct")) -> 1R X 11kV X 3C X 240 Sqmm | AL34: =IF(P34="1C",3*U34*AC34,U34*AC34) -> 1100 | AN34: =AC34*2 -> 2
A35: 13
B36: 11 KV UNIT SWGR-4UA | AN36: =AC36*2 -> 0
A37: 1 | B37: FD FAN-4A | C37: M | E37: 2450 | F37: 11 | G37: 0.77 | H37: 0.945 | I37: =IF(D37="",(E37/(1.732*F37*G37*H37)),(D37/(1.732*F37))) -> 176.72703 | J37: =IF(C37="M",7.2*I37,0) -> 1272.4346 | K37: =IF(C37="M",0.2,0) -> 0.2 | L37: 50 | M37: 0.16 | N37: =(L37*1000*SQRT(M37)/94) -> 212.76596 | O37: AIR | P37: 3C | Q37: 240 | R37: 387 | S37: 0.162 | T37: 0.088 | U37: 475 | V37: 0.89 | W37: 0.73 | X37: NA | Y37: 0 | Z37: 0 | AA37: 0.6497 | AB37: =R37*AA37 -> 251.4339 | AC37: =ROUNDUP(((I37)/AB37),0) -> 1 | AD37: =IF(AB37*AC37>=I37,"YES","NO") -> YES | AE37: =IF(C37="M",(SQRT(3)*I37*(U37/1000)*((S37/AC37)*G37+(T37/AC37)*SIN(ACOS(G37)))),(SQRT(3)*I37*(U37/1000)*((S37/AC37)*G37+(T37/AC37)*SIN(ACOS(G37))))) -> 26.30066 | AF37: =(AE37/(F37*1000))*100 -> 0.23909691 | AG37: =IF(C37="I",IF(AF37<=2,"YES","NO"),IF(AF37<=3,"YES","NO")) -> YES | AH37: =IF(C37="M",(SQRT(3)*J37*(U37/1000)*((S37/AC37)*K37+(T37/AC37)*SIN(ACOS(K37)))),"NA") -> 124.18098 | AI37: =IF(C37="M",(AH37/(F37*1000))*100,"NA") -> 1.128918 | AJ37: =IF(C37="M",IF(AI37<=10,"YES","NO"),"NA") -> YES | AK37: =IF(C37="M",IF(AND(Q37>=N37,AD37="YES",AG37="YES",AJ37="YES"),CONCATENATE(AC37,"R X ",F37,"kV X ",P37," X ",Q37," Sqmm"),"Cable size is not correct"),IF(AND(Q37>=N37,AD37="YES",AG37="YES",AJ37="NA"),CONCATENATE(AC37,"R X ",F37,"kV X ",P37," X ",Q37," Sqmm"),"Cable size is not correct")) -> 1R X 11kV X 3C X 240 Sqmm | AL37: =IF(P37="1C",3*U37*AC37,U37*AC37) -> 475 | AN37: =AC37*2 -> 2
A38: 2 | B38: PA FAN-4A | C38: M | E38: 3900 | F38: 11 | G38: 0.88 | H38: 0.95 | I38: =IF(D38="",(E38/(1.732*F38*G38*H38)),(D38/(1.732*F38))) -> 244.85995 | J38: =IF(C38="M",7.2*I38,0) -> 1762.9916 | K38: =IF(C38="M",0.2,0) -> 0.2 | L38: 50 | M38: 0.16 | N38: =(L38*1000*SQRT(M38)/94) -> 212.76596 | O38: AIR | P38: 3C | Q38: 300 | R38: 441 | S38: 0.13 | T38: 0.086 | U38: 500 | V38: 0.89 | W38: 0.73 | X38: NA | Y38: 0 | Z38: 0 | AA38: 0.6497 | AB38: =R38*AA38 -> 286.5177 | AC38: =ROUNDUP(((I38)/AB38),0) -> 1 | AD38: =IF(AB38*AC38>=I38,"YES","NO") -> YES | AE38: =IF(C38="M",(SQRT(3)*I38*(U38/1000)*((S38/AC38)*G38+(T38/AC38)*SIN(ACOS(G38)))),(SQRT(3)*I38*(U38/1000)*((S38/AC38)*G38+(T38/AC38)*SIN(ACOS(G38))))) -> 32.921049 | AF38: =(AE38/(F38*1000))*100 -> 0.29928226 | AG38: =IF(C38="I",IF(AF38<=2,"YES","NO"),IF(AF38<=3,"YES","NO")) -> YES | AH38: =IF(C38="M",(SQRT(3)*J38*(U38/1000)*((S38/AC38)*K38+(T38/AC38)*SIN(ACOS(K38)))),"NA") -> 168.34821 | AI38: =IF(C38="M",(AH38/(F38*1000))*100,"NA") -> 1.5304383 | AJ38: =IF(C38="M",IF(AI38<=10,"YES","NO"),"NA") -> YES | AK38: =IF(C38="M",IF(AND(Q38>=N38,AD38="YES",AG38="YES",AJ38="YES"),CONCATENATE(AC38,"R X ",F38,"kV X ",P38," X ",Q38," Sqmm"),"Cable size is not correct"),IF(AND(Q38>=N38,AD38="YES",AG38="YES",AJ38="NA"),CONCATENATE(AC38,"R X ",F38,"kV X ",P38," X ",Q38," Sqmm"),"Cable size is not correct")) -> 1R X 11kV X 3C X 300 Sqmm | AL38: =IF(P38="1C",3*U38*AC38,U38*AC38) -> 500 | AN38: =AC38*2 -> 2
A39: 3 | B39: CW Pump Motor#3 | C39: M | E39: 4325 | F39: 11 | G39: 0.77 | H39: 0.945 | I39: =IF(D39="",(E39/(1.732*F39*G39*H39)),(D39/(1.732*F39))) -> 311.97731 | J39: =IF(C39="M",7.2*I39,0) -> 2246.2366 | K39: =IF(C39="M",0.2,0) -> 0.2 | L39: 50 | M39: 0.16 | N39: =(L39*1000*SQRT(M39)/94) -> 212.76596 | O39: AIR | P39: 1C | Q39: 300 | R39: 387 | S39: 0.162 | T39: 0.088 | U39: 750 | V39: 0.89 | W39: 0.73 | X39: NA | Y39: 0 | Z39: 0 | AA39: 0.6497 | AB39: =R39*AA39 -> 251.4339 | AC39: 2 | AD39: =IF(AB39*AC39>=I39,"YES","NO") -> YES | AE39: =IF(C39="M",(SQRT(3)*I39*(U39/1000)*((S39/AC39)*G39+(T39/AC39)*SIN(ACOS(G39)))),(SQRT(3)*I39*(U39/1000)*((S39/AC39)*G39+(T39/AC39)*SIN(ACOS(G39))))) -> 36.654249 | AF39: =(AE39/(F39*1000))*100 -> 0.33322045 | AG39: =IF(C39="I",IF(AF39<=2,"YES","NO"),IF(AF39<=3,"YES","NO")) -> YES | AH39: =IF(C39="M",(SQRT(3)*J39*(U39/1000)*((S39/AC39)*K39+(T39/AC39)*SIN(ACOS(K39)))),"NA") -> 173.06641 | AI39: =IF(C39="M",(AH39/(F39*1000))*100,"NA") -> 1.573331 | AJ39: =IF(C39="M",IF(AI39<=10,"YES","NO"),"NA") -> YES | AK39: =IF(C39="M",IF(AND(Q39>=N39,AD39="YES",AG39="YES",AJ39="YES"),CONCATENATE(AC39,"R X ",F39,"kV X ",P39," X ",Q39," Sqmm"),"Cable size is not correct"),IF(AND(Q39>=N39,AD39="YES",AG39="YES",AJ39="NA"),CONCATENATE(AC39,"R X ",F39,"kV X ",P39," X ",Q39," Sqmm"),"Cable size is not correct")) -> 2R X 11kV X 1C X 300 Sqmm | AL39: =IF(P39="1C",3*U39*AC39,U39*AC39) -> 4500 | AN39: =AC39*2 -> 4
A40: 4 | B40: ID FAN-4A | C40: M | E40: 11350 | F40: 11 | G40: 0.85 | H40: 0.97 | I40: =IF(D40="",(E40/(1.732*F40*G40*H40)),(D40/(1.732*F40))) -> 722.54455 | J40: =IF(C40="M",7.2*I40,0) -> 5202.3207 | K40: =IF(C40="M",0.2,0) -> 0.2 | L40: 50 | M40: 0.16 | N40: =(L40*1000*SQRT(M40)/94) -> 212.76596 | O40: AIR | P40: 1C | Q40: 400 | R40: 575 | S40: 0.1018 | T40: 0.0937 | U40: 410 | V40: 0.89 | W40: 0.78 | X40: NA | Y40: 0 | Z40: 0 | AA40: 0.6942 | AB40: =R40*AA40 -> 399.165 | AC40: =ROUNDUP(((I40)/AB40),0) -> 2 | AD40: =IF(AB40*AC40>=I40,"YES","NO") -> YES | AE40: =IF(C40="M",(SQRT(3)*I40*(U40/1000)*((S40/AC40)*G40+(T40/AC40)*SIN(ACOS(G40)))),(SQRT(3)*I40*(U40/1000)*((S40/AC40)*G40+(T40/AC40)*SIN(ACOS(G40))))) -> 34.863031 | AF40: =(AE40/(F40*1000))*100 -> 0.31693664 | AG40: =IF(C40="I",IF(AF40<=2,"YES","NO"),IF(AF40<=3,"YES","NO")) -> YES | AH40: =IF(C40="M",(SQRT(3)*J40*(U40/1000)*((S40/AC40)*K40+(T40/AC40)*SIN(ACOS(K40)))),"NA") -> 207.19355 | AI40: =IF(C40="M",(AH40/(F40*1000))*100,"NA") -> 1.8835777 | AJ40: =IF(C40="M",IF(AI40<=10,"YES","NO"),"NA") -> YES | AK40: =IF(C40="M",IF(AND(Q40>=N40,AD40="YES",AG40="YES",AJ40="YES"),CONCATENATE(AC40,"R X ",F40,"kV X ",P40," X ",Q40," Sqmm"),"Cable size is not correct"),IF(AND(Q40>=N40,AD40="YES",AG40="YES",AJ40="NA"),CONCATENATE(AC40,"R X ",F40,"kV X ",P40," X ",Q40," Sqmm"),"Cable size is not correct")) -> 2R X 11kV X 1C X 400 Sqmm | AL40: =IF(P40="1C",3*U40*AC40,U40*AC40) -> 2460 | AN40: =AC40*2 -> 4
A41: 5 | B41: MDBFP Motor | C41: M | E41: 13000 | F41: 11 | G41: 0.85 | H41: 0.97 | I41: =IF(D41="",(E41/(1.732*F41*G41*H41)),(D41/(1.732*F41))) -> 827.58406 | J41: =IF(C41="M",7.2*I41,0) -> 5958.6053 | K41: =IF(C41="M",0.2,0) -> 0.2 | L41: 50 | M41: 0.16 | N41: =(L41*1000*SQRT(M41)/94) -> 212.76596 | O41: AIR | P41: 1C | Q41: 400 | R41: 575 | S41: 0.1018 | T41: 0.0937 | U41: 85 | V41: 0.89 | W41: 0.78 | X41: NA | Y41: 0 | Z41: 0 | AA41: 0.6942 | AB41: =R41*AA41 -> 399.165 | AC41: =ROUNDUP(((I41)/AB41),0) -> 3 | AD41: =IF(AB41*AC41>=I41,"YES","NO") -> YES | AE41: =IF(C41="M",(SQRT(3)*I41*(U41/1000)*((S41/AC41)*G41+(T41/AC41)*SIN(ACOS(G41)))),(SQRT(3)*I41*(U41/1000)*((S41/AC41)*G41+(T41/AC41)*SIN(ACOS(G41))))) -> 5.5189497 | AF41: =(AE41/(F41*1000))*100 -> 0.05017227 | AG41: =IF(C41="I",IF(AF41<=2,"YES","NO"),IF(AF41<=3,"YES","NO")) -> YES | AH41: =IF(C41="M",(SQRT(3)*J41*(U41/1000)*((S41/AC41)*K41+(T41/AC41)*SIN(ACOS(K41)))),"NA") -> 32.799524 | AI41: =IF(C41="M",(AH41/(F41*1000))*100,"NA") -> 0.29817749 | AJ41: =IF(C41="M",IF(AI41<=10,"YES","NO"),"NA") -> YES | AK41: =IF(C41="M",IF(AND(Q41>=N41,AD41="YES",AG41="YES",AJ41="YES"),CONCATENATE(AC41,"R X ",F41,"kV X ",P41," X ",Q41," Sqmm"),"Cable size is not correct"),IF(AND(Q41>=N41,AD41="YES",AG41="YES",AJ41="NA"),CONCATENATE(AC41,"R X ",F41,"kV X ",P41," X ",Q41," Sqmm"),"Cable size is not correct")) -> 3R X 11kV X 1C X 400 Sqmm | AL41: =IF(P41="1C",3*U41*AC41,U41*AC41) -> 765 | AN41: =AC41*2 -> 6
...

Sheet BOQ
A1: BOQ
A2: Sl.No | B2: Type of Cable | C2: Length As per Calculation | D2: Margin (10%) | E2: Total Length | F2: Rounded Up (length in M) | I2: =_xlfn.CONCAT('HT Cable'!P8," X ",'HT Cable'!Q8) -> 3C X 240 | J2: ='HT Cable'!AL8 -> 475
A3: 1 | B3: 3C X 240 | C3: =SUMIF(I2:J87,B3,J2) -> 27560 | D3: =C3*0.1 -> 2756 | E3: =C3+D3 -> 30316 | F3: 40000 | I3: =_xlfn.CONCAT('HT Cable'!P9," X ",'HT Cable'!Q9) -> 3C X 300 | J3: ='HT Cable'!AL9 -> 500
A4: 2 | B4: 3C x 300 | C4: =SUMIF(I3:J88,B4,J3) -> 2000 | D4: =C4*0.1 -> 200 | E4: =C4+D4 -> 2200 | F4: 2500 | I4: =_xlfn.CONCAT('HT Cable'!P10," X ",'HT Cable'!Q10) -> 1C X 300 | J4: ='HT Cable'!AL10 -> 4500
A5: 3 | B5: 1C x 400 | C5: =SUMIF(I4:J89,B5,J4) -> 49590 | D5: =C5*0.1 -> 4959 | E5: =C5+D5 -> 54549 | F5: 70000 | I5: =_xlfn.CONCAT('HT Cable'!P11," X ",'HT Cable'!Q11) -> 1C X 300 | J5: ='HT Cable'!AL11 -> 2460
I6: =_xlfn.CONCAT('HT Cable'!P12," X ",'HT Cable'!Q12) -> 1C X 400 | J6: ='HT Cable'!AL12 -> 765
I7: =_xlfn.CONCAT('HT Cable'!P13," X ",'HT Cable'!Q13) -> 3C X 240 | J7: ='HT Cable'!AL13 -> 460
I8: =_xlfn.CONCAT('HT Cable'!P14," X ",'HT Cable'!Q14) -> 3C X 240 | J8: ='HT Cable'!AL14 -> 470
I9: =_xlfn.CONCAT('HT Cable'!P15," X ",'HT Cable'!Q15) -> 3C X 240 | J9: ='HT Cable'!AL15 -> 460
I10: =_xlfn.CONCAT('HT Cable'!P16," X ",'HT Cable'!Q16) -> 3C X 240 | J10: ='HT Cable'!AL16 -> 490
I11: =_xlfn.CONCAT('HT Cable'!P17," X ",'HT Cable'!Q17) -> 3C X 240 | J11: ='HT Cable'!AL17 -> 490
I12: =_xlfn.CONCAT('HT Cable'!P18," X ",'HT Cable'!Q18) -> 3C X 240 | J12: ='HT Cable'!AL18 -> 490
I13: =_xlfn.CONCAT('HT Cable'!P19," X ",'HT Cable'!Q19) -> 3C X 240 | J13: ='HT Cable'!AL19 -> 1100
I14: =_xlfn.CONCAT('HT Cable'!P20," X ",'HT Cable'!Q20) -> 1C X 400 | J14: ='HT Cable'!AL20 -> 1080
I15: =_xlfn.CONCAT('HT Cable'!P21," X ",'HT Cable'!Q21) -> X | J15: ='HT Cable'!AL21 -> 0
I16: =_xlfn.CONCAT('HT Cable'!P22," X ",'HT Cable'!Q22) -> X | J16: ='HT Cable'!AL22 -> 0
I17: =_xlfn.CONCAT('HT Cable'!P23," X ",'HT Cable'!Q23) -> 3C X 240 | J17: ='HT Cable'!AL23 -> 475
... I21: =_xlfn.CONCAT('HT Cable'!P27," X ",'HT Cable'!Q27) -> 1C X 400 | J21: ='HT Cable'!AL27 -> 1080
I22: =_xlfn.CONCAT('HT Cable'!P29," X ",'HT Cable'!Q29) -> 3C X 240 | J22: ='HT Cable'!AL29 -> 470
I23: =_xlfn.CONCAT('HT Cable'!P30," X ",'HT Cable'!Q30) -> 3C X 240 | J23: ='HT Cable'!AL30 -> 460
I24: =_xlfn.CONCAT('HT Cable'!P31," X ",'HT Cable'!Q31) -> 3C X 240 | J24: ='HT Cable'!AL31 -> 490
I25: =_xlfn.CONCAT('HT Cable'!P32," X ",'HT Cable'!Q32) -> 3C X 240 | J25: ='HT Cable'!AL32 -> 490
I26: =_xlfn.CONCAT('HT Cable'!P33," X ",'HT Cable'!Q33) -> 3C X 240 | J26: ='HT Cable'!AL33 -> 490
I27: =_xlfn.CONCAT('HT Cable'!P34," X ",'HT Cable'!Q34) -> 3C X 240 | J27: ='HT Cable'!AL34 -> 1100
I28: =_xlfn.CONCAT('HT Cable'!P35," X ",'HT Cable'!Q35) -> X | J28: ='HT Cable'!AL35 -> 0
I29: =_xlfn.CONCAT('HT Cable'!P36," X ",'HT Cable'!Q36) -> X | J29: ='HT Cable'!AL36 -> 0
I30: =_xlfn.CONCAT('HT Cable'!P37," X ",'HT Cable'!Q37) -> 3C X 240 | J30: ='HT Cable'!AL37 -> 475
I31: =_xlfn.CONCAT('HT Cable'!P38," X ",'HT Cable'!Q38) -> 3C X 300 | J31: ='HT Cable'!AL38 -> 500
I32: =_xlfn.CONCAT('HT Cable'!P39," X ",'HT Cable'!Q39) -> 1C X 300 | J32: ='HT Cable'!AL39 -> 4500
I33: =_xlfn.CONCAT('HT Cable'!P40," X ",'HT Cable'!Q40) -> 1C X 400 | J33: ='HT Cable'!AL40 -> 2460
... I48: =_xlfn.CONCAT('HT Cable'!P55," X ",'HT Cable'!Q55) -> 1C X 400 | J48: ='HT Cable'!AL55 -> 2460
I49: =_xlfn.CONCAT('HT Cable'!P57," X ",'HT Cable'!Q57) -> 3C X 240 | J49: ='HT Cable'!AL57 -> 470
I50: =_xlfn.CONCAT('HT Cable'!P58," X ",'HT Cable'!Q58) -> 3C X 240 | J50: ='HT Cable'!AL58 -> 490
I51: =_xlfn.CONCAT('HT Cable'!P59," X ",'HT Cable'!Q59) -> 3C X 240 | J51: ='HT Cable'!AL59 -> 490
I52: =_xlfn.CONCAT('HT Cable'!P60," X ",'HT Cable'!Q60) -> 3C X 240 | J52: ='HT Cable'!AL60 -> 490
I53: =_xlfn.CONCAT('HT Cable'!P61," X ",'HT Cable'!Q61) -> 3C X 240 | J53: ='HT Cable'!AL61 -> 490
I54: =_xlfn.CONCAT('HT Cable'!P62," X ",'HT Cable'!Q62) -> 3C X 240 | J54: ='HT Cable'!AL62 -> 1100
I55: =_xlfn.CONCAT('HT Cable'!P63," X ",'HT Cable'!Q63) -> 1C X 400 | J55: ='HT Cable'!AL63 -> 1080
I56: =_xlfn.CONCAT('HT Cable'!P64," X ",'HT Cable'!Q64) -> X | J56: ='HT Cable'!AL64 -> 13015
I57: =_xlfn.CONCAT('HT Cable'!P65," X ",'HT Cable'!Q65) -> X | J57: ='HT Cable'!AL65 -> 0
...

Sheet Catalogue
B2: KEC Cable Catalogue
B3: Multi core cable | F3: 11/11kV | I3: Single core cable | M3: 11/11kV
B5: Size in mm2 | C5: Current carrying capacity | F5: Resistance Ohm/km | G5: Reactance Ohm/km | H5: Cable Dia | I5: Size in mm2 | J5: Current carrying capacity | M5: Resistance Ohm/km | N5: Reactance Ohm/km | O5: Cable Dia | P5: XLPE | Q5: Ambient temperature (K1) 50°C | R5: Grouping factor (K2) Duct Spacing (3 cables) 200mm Centre to Centre & 3 tier trays with spacing | T5: Ground temprature (K3) 30°C | U5: Depth of laying (K4) (1500 mm) | W5: Thermal resistivity of ground (1.5 °C.m/W) (K5)
C6: Air | D6: Ground | E6: Duct | J6: Air | K6: Ground | L6: Duct | R6: Single core | S6: Multi core | U6: Single core | V6: Multi core | W6: Single core | X6: Multi core
B7: 3C X 120 | C7: 256 | D7: 216 | E7: 188 | F7: 0.325 | G7: 0.097 | H7: 55 | I7: 1C X 150 | J7: 335 | K7: 255 | L7: 215 | M7: 0.2648 | N7: 0.1058 | O7: 30 | P7: AIR | Q7: 0.89 | R7: 0.78 | S7: 0.73
B8: 3C X 150 | C8: 288 | D8: 242 | E8: 209 | F8: 0.265 | G8: 0.094 | H8: 58 | I8: 1C X 185 | J8: 384 | K8: 284 | L8: 238 | M8: 0.2112 | N8: 0.1 | O8: 33 | P8: Duct | R8: 0.75 | S8: 0.8 | T8: 1 | U8: 0.94 | V8: 0.96 | W8: 1 | X8: 1
B9: 3C X 185 | C9: 330 | D9: 273 | E9: 240 | F9: 0.211 | G9: 0.091 | H9: 61 | I9: 1C X 240 | J9: 446 | K9: 323 | L9: 270 | M9: 0.1615 | N9: 0.098 | O9: 35 | P9: Ground | R9: 0.73 | S9: 0.77 | T9: 1 | U9: 0.94 | V9: 0.95 | W9: 1 | X9: 1
B10: 3C X 240 | C10: 387 | D10: 315 | E10: 278 | F10: 0.162 | G10: 0.088 | H10: 67 | I10: 1C X 300 | J10: 503 | K10: 357 | L10: 297 | M10: 0.1297 | N10: 0.0974 | O10: 37
B11: 3C X 300 | C11: 441 | D11: 354 | E11: 312 | F11: 0.13 | G11: 0.086 | H11: 71 | I11: 1C X 400 | J11: 575 | K11: 397 | L11: 329 | M11: 0.1018 | N11: 0.0937 | O11: 40
B12: 3C X 400 | C12: 512 | D12: 404 | E12: 356 | F12: 0.102 | G12: 0.082 | H12: 76 | I12: 1C X 500 | J12: 647 | K12: 436 | L12: 360 | M12: 0.0802 | N12: 0.0918 | O12: 43
I13: 1C X 630 | J13: 725 | K13: 476 | L13: 390 | M13: 0.0636 | N13: 0.0901 | O13: 47
