Workbook
Name a: 'LV Cable sizing_SS-1'!$C$4

Sheet Basis & Assumptions (2)
A2: Assumptions and Inputs considered for MV & LV cable sizing
A4: 1) | B4: All MV & LV cables are considered to be laid in Air / Trench with cover Cable Tray and de-rated accordingly.
A5: 2) | B5: All MV & LV multi-core cables are considered to be laid on touching formation and de-rated accordingly.
A6: 3) | B6: All MV single core cables are considered to be laid in Trefoil Formation with 150mm spacing and de-rated accordingly.
A7: 4) | B7: All LV single core cables are considered to be laid in Trefoil Formation and de-rated accordingly.
A8: 5) | B8: Over all de-rating factor considered as mentioned below based on laying condition & method of installation: LV Multi core cable - 0.66 LV Single core cable - 0.9 MV Multi core cable - 0.664 MV Single core cable - 0.819
A9: 6) | B9: The % voltage drop is limited to 3% for outgoing motor feeders , 2.5% for outgoing Power feeders and 2% to incoming feeders.
A10: 7) | B10: The % voltage drop is limited to 15% for motor feeders during starting.
A11: 8) | B11: For both MV & LV Cable sizing all required datas are taken from reference Catalogue (KEC/RPG Make Catalogue). Further final Cable sizing/BOQ shall be updated based on final vendor data during Detail Engg. Stage.
A12: 9) | B12: Desalination package both MV & LV power cable has kept under hold & same shall be revised after the finaliziation of scope.
A13: 10) | B13: Wherever the location of load is unknown, an approximate location is assumed and % voltage drop is calculated.
A14: 11) | B14: This cable sizing is done based on the "Electrical Load List, Rev-1". And same will be revised after finalization of final Loas list.
A15: 12) | B15: The below mentioned pachages are part of Vendor scope, henece respective package Cable sizing / cable boq has not included. 1. Ammonia Storage area, 2. ASU Package, 3. Nitrogen Package, 4. Flare area Package, 5. Cooling tower Package. 6. ETP Package. 7. Desalination Sea Water Treatment Package. 8. Sea Water Intake system. 9. Electrolyzer Area Package.
B18: from ups sub db to I&C instrument cable lnot considered

Sheet Basis & Assumptions
A2: Basis & Assumptions considered for MV & LV cable sizing
A4: 1) | B4: All MV & LV cables are considered to be laid in Air / Trench with cover Cable Tray and de-rated accordingly.
A5: 2) | B5: All MV & LV multi-core cables are considered to be laid on touching formation and de-rated accordingly.
A6: 3) | B6: All MV single core cables are considered to be laid in Trefoil Formation with 150mm spacing and de-rated accordingly.
A7: 4) | B7: All LV single core cables are considered to be laid in Trefoil Formation and de-rated accordingly.
A8: 5) | B8: Over all de-rating factor considered as mentioned below based on laying condition & method of installation: LV Multi core cable - 0.587 LV Single core cable - 0.721 MV Multi core cable - 0.599 MV Single core cable - 0.738
A9: 6) | B9: The % voltage drop is limited to 3% for outgoing motor feeders , 2.5% for outgoing Power feeders and 2% to incoming feeders.
A10: 7) | B10: The % voltage drop is limited to 15% for motor feeders during starting.
A11: 8) | B11: For both MV & LV Cable sizing all required datas are taken from reference Catalogue (KEC/RPG Make Catalogue). Further final Cable sizing/BOQ shall be updated based on final vendor data during Detail Engg. Stage.
A12: 9) | B12: 1). All incoming cable from solar, Grid, BESS to 33kV Switchgear (MSB) cable is part of Vendor/ACME scope henace same sizing/BOQ not considered. 2). In Desalination package: a) Incoming Cable from LV VFD to PMCC-4, 11kV Switchgaer to MV VFD's, both MV & LV power cables are inculded in the sizing/BOQ. b) Further from PMCC to Motor/LCS, from LV VFD to motor/LCS, from MV VFD to motor/LCS both MV & LV power cable BOQ is part of Vendor/ACME scope hence same has not included in the sizing/BOQ.
A13: 10) | B13: Wherever the location of load is unknown, an approximate location is assumed and % voltage drop is calculated.
A14: 11) | B14: This cable sizing is done based on the "Electrical Load List, Rev-1". And same will be revised after finalization of final Loas list.
A15: 12) | B15: Cable from UPS DB/ Sub UPS DB to Instrument is not included in this sizing & same shall be considered in Instrument cable schedule/BOQ.
A16: 13) | B16: The below mentioned packages are part of Vendor scope, henece respective package Cable sizing / cable boq has not included. 1. Ammonia Storage area, 2. ASU Package, 3. Nitrogen Package, 4. Flare area Package, 5. Cooling tower Package. 6. ETP Package. 7. Desalination Sea Water Treatment Package. 8. Sea Water Intake system. 9. Electrolyzer Area Package.

Sheet Tray Sizing
B4: Cable Tray Sections | E4: A1 | F4: A | G4: B | H4: B1 | I4: C | J4: D | K4: D1 | L4: D2 | M4: D3 | N4: E | O4: E0 | P4: E1 | Q4: E2 | R4: E3 | S4: E4 | T4: E5 | U4: E6 | V4: F | W4: G | X4: G1 | Y4: G2 | Z4: G3 | AA4: G4 | AB4: H | AC4: I | AD4: J | AE4: J1 | AF4: J2 | AG4: J3 | AH4: K | AI4: L | AJ4: L1 | AK4: L2 | AL4: L3 | AM4: L4 | AN4: M | AO4: N | AP4: O | AQ4: O1 | AR4: P | AS4: Q | AT4: Q1 | AU4: Q2 | AV4: Q3 | AW4: R | AX4: R1 | AY4: R2 | AZ4: S | BA4: T
B6: 33kV MV Power Cable Trays
B7: MV Cable sizing-33kV | C7: Total Cable Dia | E7: =SUMIF(#REF!,'Tray Sizing'!E$4,#REF!) -> #REF! | F7: =SUMIF(#REF!,'Tray Sizing'!F$4,#REF!) -> #REF! | G7: =SUMIF(#REF!,'Tray Sizing'!G$4,#REF!) -> #REF! | H7: =SUMIF(#REF!,'Tray Sizing'!H$4,#REF!) -> #REF! | I7: =SUMIF(#REF!,'Tray Sizing'!I$4,#REF!) -> #REF! | J7: =SUMIF(#REF!,'Tray Sizing'!J$4,#REF!) -> #REF! | K7: =SUMIF(#REF!,'Tray Sizing'!K$4,#REF!) -> #REF! | L7: =SUMIF(#REF!,'Tray Sizing'!L$4,#REF!) -> #REF! | ... BA7: =SUMIF(#REF!,'Tray Sizing'!BA$4,#REF!) -> #REF!
B9: Total Cable Tray Dia required with 20% Margin | C9: with 20% marging | E9: =E7*1.2 -> #REF! | F9: =F7*1.2 -> #REF! | G9: =G7*1.2 -> #REF! | H9: =H7*1.2 -> #REF! | I9: =I7*1.2 -> #REF! | J9: =J7*1.2 -> #REF! | K9: =K7*1.2 -> #REF! | L9: =L7*1.2 -> #REF! | ... BA9: =BA7*1.2 -> #REF!
C11: 600 | E11: =E9/$C$11 -> #REF! | F11: =F9/$C$11 -> #REF! | G11: =G9/$C$11 -> #REF! | H11: =H9/$C$11 -> #REF! | I11: =I9/$C$11 -> #REF! | J11: =J9/$C$11 -> #REF! | K11: =K9/$C$11 -> #REF! | L11: =L9/$C$11 -> #REF! | ... BA11: =BA9/$C$11 -> #REF!
B12: 33kV MV Power Cable Trays | E12: =ROUNDUP(E11,0) -> #REF! | F12: =ROUNDUP(F11,0) -> #REF! | G12: =ROUNDUP(G11,0) -> #REF! | H12: =ROUNDUP(H11,0) -> #REF! | I12: =ROUNDUP(I11,0) -> #REF! | J12: =ROUNDUP(J11,0) -> #REF! | K12: =ROUNDUP(K11,0) -> #REF! | L12: =ROUNDUP(L11,0) -> #REF! | ... BA12: =ROUNDUP(BA11,0) -> #REF!
B18: 11kV MV Power Cable Trays
B20: MV Cable sizing-11kV | E20: =SUMIF('MV Cable sizing-11kV'!$DW$4:$GN$4,'Tray Sizing'!E$4,'MV Cable sizing-11kV'!$DW$85:$GN$85) -> 0 | F20: =SUMIF('MV Cable sizing-11kV'!$DW$4:$GN$4,'Tray Sizing'!F$4,'MV Cable sizing-11kV'!$DW$85:$GN$85) -> 1979 | G20: =SUMIF('MV Cable sizing-11kV'!$DW$4:$GN$4,'Tray Sizing'!G$4,'MV Cable sizing-11kV'!$DW$85:$GN$85) -> 0 | H20: =SUMIF('MV Cable sizing-11kV'!$DW$4:$GN$4,'Tray Sizing'!H$4,'MV Cable sizing-11kV'!$DW$85:$GN$85) -> 0 | I20: =SUMIF('MV Cable sizing-11kV'!$DW$4:$GN$4,'Tray Sizing'!I$4,'MV Cable sizing-11kV'!$DW$85:$GN$85) -> 1550 | J20: =SUMIF('MV Cable sizing-11kV'!$DW$4:$GN$4,'Tray Sizing'!J$4,'MV Cable sizing-11kV'!$DW$85:$GN$85) -> 1336 | K20: =SUMIF('MV Cable sizing-11kV'!$DW$4:$GN$4,'Tray Sizing'!K$4,'MV Cable sizing-11kV'!$DW$85:$GN$85) -> 0 | L20: =SUMIF('MV Cable sizing-11kV'!$DW$4:$GN$4,'Tray Sizing'!L$4,'MV Cable sizing-11kV'!$DW$85:$GN$85) -> 0 | ... BA20: =SUMIF('MV Cable sizing-11kV'!$DW$4:$GN$4,'Tray Sizing'!BA$4,'MV Cable sizing-11kV'!$DW$85:$GN$85) -> 0
B22: Total Cable Tray Dia required with 20% Margin | E22: =E20*1.2 -> 0 | F22: =F20*1.2 -> 2374.8 | G22: =G20*1.2 -> 0 | H22: =H20*1.2 -> 0 | I22: =I20*1.2 -> 1860 | J22: =J20*1.2 -> 1603.2 | K22: =K20*1.2 -> 0 | L22: =L20*1.2 -> 0 | ... BA22: =BA20*1.2 -> 0
B27: 11kV Power Cables - Ladder Type Tray | C27: 600 | E27: =E22/$C$27 -> 0 | F27: =F22/$C$27 -> 3.958 | G27: =G22/$C$27 -> 0 | H27: =H22/$C$27 -> 0 | I27: =I22/$C$27 -> 3.1 | J27: =J22/$C$27 -> 2.672 | K27: =K22/$C$27 -> 0 | L27: =L22/$C$27 -> 0 | ... BA27: =BA22/$C$27 -> 0
E29: =ROUNDUP(E27,0) -> 0 | F29: =ROUNDUP(F27,0) -> 4 | G29: =ROUNDUP(G27,0) -> 0 | H29: =ROUNDUP(H27,0) -> 0 | I29: =ROUNDUP(I27,0) -> 4 | J29: 2 | K29: 0 | L29: 0 | M29: 0 | N29: 2 | O29: 0 | P29: 1 | Q29: =ROUNDUP(Q27,0) -> 2 | R29: 0 | S29: 0 | T29: 0 | U29: 0 | V29: 1 | W29: 1 | X29: =ROUNDUP(X27,0) -> 0 | Y29: =ROUNDUP(Y27,0) -> 0 | Z29: =ROUNDUP(Z27,0) -> 0 | AA29: =ROUNDUP(AA27,0) -> 0 | AB29: 0 | AC29: =ROUNDUP(AC27,0) -> 2 | AD29: 0 | AE29: =ROUNDUP(AE27,0) -> 0 | AF29: 0 | AG29: 0 | AH29: 0 | AI29: =ROUNDUP(AI27,0) -> 0 | AJ29: =ROUNDUP(AJ27,0) -> 0 | AK29: =ROUNDUP(AK27,0) -> 0 | AL29: =ROUNDUP(AL27,0) -> 0 | AM29: =ROUNDUP(AM27,0) -> 0 | AN29: =ROUNDUP(AN27,0) -> 0 | AO29: =ROUNDUP(AO27,0) -> 0 | AP29: =ROUNDUP(AP27,0) -> 0 | ... AR29: =ROUNDUP(AR27,0) -> 0 | AS29: 0 | AT29: =ROUNDUP(AT27,0) -> 0 | AU29: 0 | AV29: =ROUNDUP(AV27,0) -> 0 | AW29: 0 | AX29: 0 | AY29: 0 | AZ29: =ROUNDUP(AZ27,0) -> 0 | BA29: =ROUNDUP(BA27,0) -> 0
C31: 450 | R31: =ROUNDUP(R27,0) -> 1 | AB31: =ROUNDUP(AB27,0) -> 1 | AD31: =ROUNDUP(AD27,0) -> 1 | AS31: =ROUNDUP(AS27,0) -> 1
C33: 300 | J33: 1 | K33: =ROUNDUP(K27,0) -> 0 | L33: =ROUNDUP(L27,0) -> 0 | M33: =ROUNDUP(M27,0) -> 0 | N33: 1 | O33: =ROUNDUP(O27,0) -> 0 | P33: 1 | S33: =ROUNDUP(S27,0) -> 1 | T33: =ROUNDUP(T27,0) -> 1 | U33: =ROUNDUP(U27,0) -> 0 | AF33: =ROUNDUP(AF27,0) -> 0 | AG33: =ROUNDUP(AG27,0) -> 0 | AH33: =ROUNDUP(AH27,0) -> 1 | AU33: =ROUNDUP(AU27,0) -> 1 | AW33: =ROUNDUP(AW27,0) -> 1 | AX33: =ROUNDUP(AX27,0) -> 1 | AY33: =ROUNDUP(AY27,0) -> 0
B35: LV Power Cable Trays
B36: LV Cable sizing_SS-1_Power Cables | E36: =SUMIF('LV Cable sizing_SS-1'!$DW$4:$FO$4,'Tray Sizing'!E$4,'LV Cable sizing_SS-1'!$DW$448:$FO$448) -> 719 | F36: =SUMIF('LV Cable sizing_SS-1'!$DW$4:$FO$4,'Tray Sizing'!F$4,'LV Cable sizing_SS-1'!$DW$448:$FO$448) -> #N/A | G36: =SUMIF('LV Cable sizing_SS-1'!$DW$4:$FO$4,'Tray Sizing'!G$4,'LV Cable sizing_SS-1'!$DW$448:$FO$448) -> #N/A | H36: =SUMIF('LV Cable sizing_SS-1'!$DW$4:$FO$4,'Tray Sizing'!H$4,'LV Cable sizing_SS-1'!$DW$448:$FO$448) -> 697 | I36: =SUMIF('LV Cable sizing_SS-1'!$DW$4:$FO$4,'Tray Sizing'!I$4,'LV Cable sizing_SS-1'!$DW$448:$FO$448) -> 3779 | J36: =SUMIF('LV Cable sizing_SS-1'!$DW$4:$FO$4,'Tray Sizing'!J$4,'LV Cable sizing_SS-1'!$DW$448:$FO$448) -> 3584 | K36: =SUMIF('LV Cable sizing_SS-1'!$DW$4:$FO$4,'Tray Sizing'!K$4,'LV Cable sizing_SS-1'!$DW$448:$FO$448) -> 95 | L36: =SUMIF('LV Cable sizing_SS-1'!$DW$4:$FO$4,'Tray Sizing'!L$4,'LV Cable sizing_SS-1'!$DW$448:$FO$448) -> 21 | ... BA36: =SUMIF('LV Cable sizing_SS-1'!$DW$4:$FO$4,'Tray Sizing'!BA$4,'LV Cable sizing_SS-1'!$DW$448:$FO$448) -> 0
B38: LV Cable sizing_SS-2_Power Cables | E38: =SUMIF('LV Cable sizing_SS-2'!$DW$4:$FZ$4,'Tray Sizing'!E$4,'LV Cable sizing_SS-2'!$DW$283:$FZ$283) -> 0 | F38: =SUMIF('LV Cable sizing_SS-2'!$DW$4:$FZ$4,'Tray Sizing'!F$4,'LV Cable sizing_SS-2'!$DW$283:$FZ$283) -> 0 | G38: =SUMIF('LV Cable sizing_SS-2'!$DW$4:$FZ$4,'Tray Sizing'!G$4,'LV Cable sizing_SS-2'!$DW$283:$FZ$283) -> 0 | H38: =SUMIF('LV Cable sizing_SS-2'!$DW$4:$FZ$4,'Tray Sizing'!H$4,'LV Cable sizing_SS-2'!$DW$283:$FZ$283) -> 0 | I38: =SUMIF('LV Cable sizing_SS-2'!$DW$4:$FZ$4,'Tray Sizing'!I$4,'LV Cable sizing_SS-2'!$DW$283:$FZ$283) -> 0 | J38: =SUMIF('LV Cable sizing_SS-2'!$DW$4:$FZ$4,'Tray Sizing'!J$4,'LV Cable sizing_SS-2'!$DW$283:$FZ$283) -> 0 | K38: =SUMIF('LV Cable sizing_SS-2'!$DW$4:$FZ$4,'Tray Sizing'!K$4,'LV Cable sizing_SS-2'!$DW$283:$FZ$283) -> 0 | L38: =SUMIF('LV Cable sizing_SS-2'!$DW$4:$FZ$4,'Tray Sizing'!L$4,'LV Cable sizing_SS-2'!$DW$283:$FZ$283) -> 0 | ... BA38: =SUMIF('LV Cable sizing_SS-2'!$DW$4:$FZ$4,'Tray Sizing'!BA$4,'LV Cable sizing_SS-2'!$DW$283:$FZ$283) -> 0
B40: LV Cable sizing_SS-3_Power Cables | E40: =SUMIF('LV Cable sizing_SS-3'!$DW$4:$FZ$4,'Tray Sizing'!E$4,'LV Cable sizing_SS-3'!$DW$102:$FZ$102) -> 0 | F40: =SUMIF('LV Cable sizing_SS-3'!$DW$4:$FZ$4,'Tray Sizing'!F$4,'LV Cable sizing_SS-3'!$DW$102:$FZ$102) -> 0 | G40: =SUMIF('LV Cable sizing_SS-3'!$DW$4:$FZ$4,'Tray Sizing'!G$4,'LV Cable sizing_SS-3'!$DW$102:$FZ$102) -> 0 | H40: =SUMIF('LV Cable sizing_SS-3'!$DW$4:$FZ$4,'Tray Sizing'!H$4,'LV Cable sizing_SS-3'!$DW$102:$FZ$102) -> 0 | I40: =SUMIF('LV Cable sizing_SS-3'!$DW$4:$FZ$4,'Tray Sizing'!I$4,'LV Cable sizing_SS-3'!$DW$102:$FZ$102) -> 0 | J40: =SUMIF('LV Cable sizing_SS-3'!$DW$4:$FZ$4,'Tray Sizing'!J$4,'LV Cable sizing_SS-3'!$DW$102:$FZ$102) -> 0 | K40: =SUMIF('LV Cable sizing_SS-3'!$DW$4:$FZ$4,'Tray Sizing'!K$4,'LV Cable sizing_SS-3'!$DW$102:$FZ$102) -> 0 | L40: =SUMIF('LV Cable sizing_SS-3'!$DW$4:$FZ$4,'Tray Sizing'!L$4,'LV Cable sizing_SS-3'!$DW$102:$FZ$102) -> 0 | ... BA40: =SUMIF('LV Cable sizing_SS-3'!$DW$4:$FZ$4,'Tray Sizing'!BA$4,'LV Cable sizing_SS-3'!$DW$102:$FZ$102) -> 0
B42: LV Cable sizing_SS-4_Power Cables | E42: =SUMIF(#REF!,'Tray Sizing'!E$4,#REF!) -> #REF! | F42: =SUMIF(#REF!,'Tray Sizing'!F$4,#REF!) -> #REF! | G42: =SUMIF(#REF!,'Tray Sizing'!G$4,#REF!) -> #REF! | H42: =SUMIF(#REF!,'Tray Sizing'!H$4,#REF!) -> #REF! | I42: =SUMIF(#REF!,'Tray Sizing'!I$4,#REF!) -> #REF! | J42: =SUMIF(#REF!,'Tray Sizing'!J$4,#REF!) -> #REF! | K42: =SUMIF(#REF!,'Tray Sizing'!K$4,#REF!) -> #REF! | L42: =SUMIF(#REF!,'Tray Sizing'!L$4,#REF!) -> #REF! | ... BA42: =SUMIF(#REF!,'Tray Sizing'!BA$4,#REF!) -> #REF!
B44: LV Cable sizing_SS-5_Power Cables
B46: LV Cable sizing_SS-6_Power Cables
B48: Total Cable Tray Dia required for LV power Cable | E48: =SUM(E36:E47) -> #REF! | F48: =SUM(F36:F47) -> #N/A | G48: =SUM(G36:G47) -> #N/A | H48: =SUM(H36:H47) -> #REF! | I48: =SUM(I36:I47) -> #REF! | J48: =SUM(J36:J47) -> #REF! | K48: =SUM(K36:K47) -> #REF! | L48: =SUM(L36:L47) -> #REF! | ... BA48: =SUM(BA36:BA47) -> #REF!
B50: Total Cable Tray Dia required with 20% Margin | E50: =E48*1.2 -> #REF! | F50: =F48*1.2 -> #N/A | G50: =G48*1.2 -> #N/A | H50: =H48*1.2 -> #REF! | I50: =I48*1.2 -> #REF! | J50: =J48*1.2 -> #REF! | K50: =K48*1.2 -> #REF! | L50: =L48*1.2 -> #REF! | ... BA50: =BA48*1.2 -> #REF!
B52: LV Power Cables - Ladder Type Tray | C52: 600 | E52: =E50/$C$52 -> #REF! | F52: =F50/$C$52 -> #N/A | G52: =G50/$C$52 -> #N/A | H52: =H50/$C$52 -> #REF! | I52: =I50/$C$52 -> #REF! | J52: =J50/$C$52 -> #REF! | K52: =K50/$C$52 -> #REF! | L52: =L50/$C$52 -> #REF! | ... BA52: =BA50/$C$52 -> #REF!
E54: =ROUNDUP(E52,0) -> #REF! | F54: 10 | G54: =ROUNDUP(G52,0) -> #N/A | H54: =ROUNDUP(H52,0) -> #REF! | I54: =ROUNDUP(I52,0) -> #REF! | J54: =ROUNDUP(J52,0) -> #REF! | K54: =ROUNDUP(K52,0) -> #REF! | L54: 0 | M54: =ROUNDUP(M52,0) -> #REF! | N54: =ROUNDUP(N52,0) -> #REF! | O54: =ROUNDUP(O52,0) -> #REF! | P54: 7 | Q54: 4 | R54: 3 | S54: 2 | T54: 1 | U54: 0 | V54: =ROUNDUP(V52,0) -> #REF! | W54: =ROUNDUP(W52,0) -> #REF! | X54: 1 | Y54: 0 | Z54: 1 | AA54: 0 | AB54: 1 | AC54: =ROUNDUP(AC52,0) -> #REF! | AD54: =ROUNDUP(AD52,0) -> #REF! | AE54: =ROUNDUP(AE52,0) -> #REF! | AF54: =ROUNDUP(AF52,0) -> #REF! | AG54: 0 | AH54: =ROUNDUP(AH52,0) -> #REF! | AI54: =ROUNDUP(AI52,0) -> #REF! | AJ54: =ROUNDUP(AJ52,0) -> #REF! | AK54: =ROUNDUP(AK52,0) -> #REF! | AL54: =ROUNDUP(AL52,0) -> #REF! | AM54: =ROUNDUP(AM52,0) -> #REF! | AN54: =ROUNDUP(AN52,0) -> #REF! | AO54: 0 | AP54: 0 | AQ54: 0 | AR54: =ROUNDUP(AR52,0) -> #REF! | AS54: 0 | AT54: 0 | AU54: 0 | AV54: 5 | AW54: 5 | AX54: 4 | AY54: =ROUNDUP(AY52,0) -> #REF! | AZ54: 2 | BA54: =ROUNDUP(BA52,0) -> #REF!
C56: 450 | Q56: 1 | U56: =ROUNDUP(U52,0) -> #REF! | AS56: =ROUNDUP(AS52,0) -> #REF!
C58: 300 | L58: =ROUNDUP(L52,0) -> #REF! | R58: 1 | S58: 1 | T58: 1 | X58: 1 | Y58: =ROUNDUP(Y52,0) -> #REF! | Z58: 1 | AA58: =ROUNDUP(AA52,0) -> #REF! | AB58: 1 | AG58: =ROUNDUP(AG52,0) -> #REF! | AO58: =ROUNDUP(AO52,0) -> #REF! | AP58: =ROUNDUP(AP52,0) -> #REF! | AQ58: =ROUNDUP(AQ52,0) -> #REF! | AT58: =ROUNDUP(AT52,0) -> #REF! | AU58: 1 | AX58: 1 | AZ58: 1
B60: LV Control Cables - Ladder Type Tray | C60: 600 | E60: 1 | F60: 1 | G60: 1 | H60: 1 | I60: 1 | J60: 1 | K60: 1 | L60: 1 | M60: 1 | N60: 1 | O60: 1 | P60: 1 | Q60: 1 | R60: 1 | S60: 1 | T60: 1 | U60: 0 | V60: 0 | W60: 1 | X60: 1 | Y60: 0 | Z60: 1 | AA60: 0 | AB60: 1 | AC60: 1 | AD60: 1 | AE60: 1 | AF60: 1 | AG60: 0 | AH60: 1 | AI60: 1 | AJ60: 1 | AK60: 1 | AL60: 1 | AM60: 1 | AN60: 1 | AO60: 0 | AP60: 0 | AQ60: 0 | AR60: 1 | AS60: 1 | AT60: 1 | AU60: 0 | AV60: 1 | AW60: 1 | AX60: 1 | AY60: 0 | AZ60: 0 | BA60: 0
C62: 450 | U62: 1
C64: 300 | V64: =ROUNDUP(V54,0) -> #REF! | Y64: =ROUNDUP(Y58,0) -> #REF! | AA64: =ROUNDUP(AA58,0) -> #REF! | AC64: =ROUNDUP(AC58,0) -> 0 | AD64: =ROUNDUP(AD58,0) -> 0 | AG64: =ROUNDUP(AG58,0) -> #REF! | AO64: 0 | AP64: =ROUNDUP(AP58,0) -> #REF! | AQ64: =ROUNDUP(AQ58,0) -> #REF! | AS64: 1 | AT64: =ROUNDUP(AT58,0) -> #REF! | AU64: =ROUNDUP(AU58,0) -> 1 | AV64: 1 | AW64: 1 | AX64: 1 | AY64: 0 | AZ64: 1 | BA64: 1
B67: Instrumentation Cable Trays | E67: 1 | F67: 3 | G67: 3 | H67: 14 | I67: 8 | J67: 4 | K67: 4 | L67: 4 | M67: 4 | N67: 4 | O67: 4 | P67: 4 | Q67: 4 | R67: 4 | S67: 4 | T67: 4 | U67: 4 | AO67: 2 | AP67: 2 | AR67: 2 | AS67: 2 | AT67: 1 | AU67: 2 | AV67: 2 | AW67: 2 | AX67: 2 | AY67: 1 | AZ67: 1 | BA67: 1
E69: 1 | F69: 2 | G69: 12 | H69: 2 | I69: 8 | J69: 4 | K69: 4 | L69: 4 | M69: 4 | N69: 4 | O69: 4 | P69: 4 | Q69: 4 | R69: 4 | S69: 4 | T69: 4 | U69: 4 | AO69: 2 | AP69: 2 | AR69: 2
B71: Instrumentation Cable Trays
B72: IS Cable Tray | C72: Total Cable Dia
C73: 600
C74: 450
C75: 300
B78: Non IS Cable Tray | C78: Total Cable Dia
C79: 600
C80: 450
C81: 300
...

Sheet Catalogue Aluminium
B3: LV Cable Catalogue (KEC/RPG Make Catalogue Attached) | J3: DERATING FACTORS
B5: 1-core cable | G5: 0.6/1.0 kV
B7: Size in mm2 | C7: Current carrying capacity | F7: AC Resistance Ohm/km 90°C | G7: Reactance Ohm/km | H7: Cable Dia | I7: LV | J7: XLPE | K7: Ambient temperature (50°C) (K1) | L7: Grouping factor (K2) 4 trafoil groups, 6 tier trays with Touching | N7: Ground temperature (35°C) (K3) | O7: Depth of laying (900 mm) (K4) | Q7: Thermal resistivity of ground (1.2 K.m/W) (K5)
C8: Air | D8: Ground | E8: Duct | L8: Single core (Trefoil Formation with Touching) | M8: Multi core (Touching) | O8: Single core | P8: Multi core | Q8: Cable Size | R8: Single core | S8: Multi core
B9: 1C X 185 | C9: 370 | D9: 290 | E9: 224 | F9: 0.21 | G9: 0.0875 | H9: 26 | I9: 690/400V | J9: AIR | K9: 0.89 | L9: 0.81 | M9: 0.66 | N9: NA | O9: NA | P9: NA
B10: 1C X 240 | C10: 445 | D10: 340 | E10: 283 | F10: 0.16 | G10: 0.0866 | H10: 28 | J10: Duct | K10: NA | L10: 0.74 | M10: 0.71 | N10: 0.96 | O10: 0.98 | P10: 0.98 | Q10: 1.5 | R10: 1.09 | S10: 1.05
B11: 1C X 300 | C11: 514 | D11: 382 | E11: 317 | F11: 0.128 | G11: 0.0857 | H11: 31 | J11: Ground | K11: NA | L11: 0.61 | M11: 0.54 | N11: 0.96 | O11: 0.98 | P11: 0.98 | Q11: 2.5 | R11: 1.09 | S11: 1.05
B12: 1C X 400 | C12: 605 | D12: 437 | E12: 370 | F12: 0.1 | G12: 0.0855 | H12: 34 | J12: Trench with cover | K12: 0.89 | L12: 0.81 | M12: 0.66 | N12: NA | O12: NA | P12: NA | Q12: 4 | R12: 1.09 | S12: 1.05 | AA12: 0.76
B13: 1C X 500 | C13: 704 | D13: 500 | E13: 428 | F13: 0.0774 | G13: 0.0851 | H13: 38 | Q13: 6 | R13: 1.09 | S13: 1.05
B14: 1C X 630 | C14: 822 | D14: 565 | E14: 464 | F14: 0.06 | G14: 0.0843 | H14: 42 | Q14: 10 | R14: 1.09 | S14: 1.06
Q15: 16 | R15: 1.09 | S15: 1.06
B16: 2-core cable | G16: 0.6/1.0 kV | Q16: 25 | R16: 1.09 | S16: 1.08
B17: Size in mm2 | C17: Current carrying capacity | F17: AC Resistance Ohm/km 90°C | G17: Reactance Ohm/km | H17: Cable Dia | Q17: 35 | R17: 1.09 | S17: 1.08
C18: Air | D18: Ground | E18: Duct | Q18: 50 | R18: 1.09 | S18: 1.08
B19: 2C X 1.5 | C19: 29 | D19: 33 | E19: 29 | F19: 15.5 | G19: 0.108 | H19: 12 | Q19: 70 | R19: 1.1 | S19: 1.08
B20: 2C X 2.5 | C20: 39 | D20: 43 | E20: 37 | F20: 9.48 | G20: 0.1007 | H20: 13 | Q20: 95 | R20: 1.1 | S20: 1.08
B21: 2C X 4 | C21: 48 | D21: 54 | E21: 46 | F21: 5.9 | G21: 0.0947 | H21: 14 | Q21: 120 | R21: 1.1 | S21: 1.08
B22: 2C X 6 | C22: 59 | D22: 66 | E22: 58 | F22: 3.94 | G22: 0.0902 | H22: 15 | Q22: 150 | R22: 1.1 | S22: 1.09
B23: 2C X 10 | C23: 62 | D23: 70 | E23: 57 | F23: 3.94 | G23: 0.0852 | H23: 17 | Q23: 185 | R23: 1.1 | S23: 1.09
B24: 2C X 16 | C24: 79 | D24: 90 | E24: 75 | F24: 2.44 | G24: 0.0815 | H24: 18 | Q24: 240 | R24: 1.1 | S24: 1.09
B25: 2C X 25 | C25: 108 | D25: 117 | E25: 99 | F25: 1.54 | G25: 0.0816 | H25: 20 | Q25: 300 | R25: 1.1 | S25: 1.09
B26: 2C X 35 | C26: 143 | D26: 140 | E26: 117 | F26: 1.11 | G26: 0.0794 | H26: 21 | Q26: 400 | R26: 1.11 | S26: 1.1
B27: 2C X 50 | C27: 173 | D27: 168 | E27: 143 | F27: 0.82 | G27: 0.0792 | H27: 24 | Q27: 500 | R27: 1.11 | S27: 1.1
B28: 2C X 70 | C28: 212 | D28: 202 | E28: 177 | F28: 0.567 | G28: 0.0752 | H28: 27 | Q28: 630 | R28: 1.11 | S28: 1.1
B29: 2C X 95 | C29: 257 | D29: 243 | E29: 217 | F29: 0.41 | G29: 0.0734 | H29: 30
B30: 2C X 120 | C30: 295 | D30: 273 | E30: 247 | F30: 0.324 | G30: 0.0726 | H30: 32
B31: 2C X 150 | C31: 342 | D31: 310 | E31: 305 | F31: 0.264 | G31: 0.0732 | H31: 35
B32: 2C X 185 | C32: 395 | D32: 350 | E32: 345 | F32: 0.21 | G32: 0.0727 | H32: 39
B33: 2C X 240 | C33: 465 | D33: 401 | E33: 393 | F33: 0.16 | G33: 0.0719 | H33: 44
B34: 2C X 300 | C34: 532 | D34: 458 | E34: 453 | F34: 0.128 | G34: 0.0711 | H34: 48
B35: 2C X 400 | C35: 622 | D35: 505 | E35: 553 | F35: 0.1 | G35: 0.0705 | H35: 54
B37: 3-core cable | G37: 0.6/1.0 kV
B38: Size in mm2 | C38: Current carrying capacity | F38: AC Resistance Ohm/km 90°C | G38: Reactance Ohm/km | H38: Cable Dia
C39: Air | D39: Ground | E39: Duct
B40: 3C X 1.5 | C40: 22 | D40: 25 | E40: 22 | F40: 15.5 | G40: 0.108 | H40: 13 | AA40: 13.2
B41: 3C X 2.5 | C41: 28 | D41: 34 | E41: 28 | F41: 9.48 | G41: 0.1007 | H41: 14 | AA41: 16.8
B42: 3C X 4 | C42: 38 | D42: 44 | E42: 37 | F42: 5.9 | G42: 0.0947 | H42: 15 | AA42: 22.8
B43: 3C X 6 | C43: 51 | D43: 55 | E43: 46 | F43: 3.94 | G43: 0.0902 | H43: 16 | AA43: 30.6
B44: 3C X 10 | C44: 60 | D44: 57 | E44: 48 | F44: 3.94 | G44: 0.0852 | H44: 19 | AA44: 36
B45: 3C X 16 | C45: 70 | D45: 73 | E45: 61 | F45: 2.44 | G45: 0.0815 | H45: 19 | AA45: 42
...

Sheet MV Cable sizing-11kV
A2: MV (11kV) POWER CABLE SIZING
A3: Sl. No | D3: LOAD | Q3: SHORT CIRCUIT CURRENT WITHSTAND CAPABILITY | T3: CABLE DATA | AI3: DERATING FACTOR | AO3: CURRENT CARRYING CAPACITY | AR3: RUNNING CONDITION VOLTAGE DROP | AT3: MOTOR STARTING VOLTAGE DROP | AV3: Selected Cable Size
B4: Tag No. | C4: From | D4: Description | E4: Equipment Location | F4: BUS | G4: Type of feeder | H4: Rated power | I4: UNIT (kW / kVA) | J4: 3Phase / 1Phase | K4: Rated Voltage (V) | L4: Power factor | M4: Efficiency | N4: Rated full load current | O4: Motor starting current | P4: Motor starting power factor | Q4: Short circuit current of switchboard (kA) | R4: Short circuit current withstand duration (sec) | S4: Minimum size required for Short circuit withstand capacity (Sq.mm) | T4: Installation | U4: No. of Cores | V4: Size in (Sq.mm) | W4: Cable size | X4: Cable size With (PE) Core | Y4: Cable Voltage (kV) | Z4: Current Rating of the Cable (A) | AA4: Cable resistance at 90°C (Ohm / Ph / km) | AB4: Cable reactance at 50Hz (Ohm / Ph / km) | AC4: Cable Length with in Electrical Building (m) | AD4: Cable Length from Electrical Building to Equipment (m) | AE4: Cable length Riser & Dropper (m) | AF4: Cable length both side dropping & Termination (m) | AG4: Spare 10% | AH4: Cable length for each run (m) | AI4: Ambient temperature (K1) | AJ4: Grouping factor (K2) | AK4: Ground temperature (K3) | AL4: Depth of laying (K4) | AM4: Thermal resistivity of ground (K5) | AN4: Overall derating factor | AO4: Derated current carrying capacity (A) | AP4: No. of Runs | AQ4: Derated current > Rated current | AR4: % VOLTAGE DROP DURING RUNNING CONDITION | AS4: % VOLTAGE DROP WITHIN PERMISSIBLE LIMIT (YES/NO) | AT4: % VOLTAGE DROP DURING STARTING CONDITION | AU4: % VOLTAGE DROP WITHIN PERMISSIBLE LIMIT DURING STARTING CONDITION (YES/NO) | AV4: Selected cable size | AW4: Selected cable size | AX4: Total Cable Length in meters | AY4: Remarks | AZ4: No. of End Termination | BA4: Cable Route(Sections) | BB4: Dia of the conductor (mm) | BC4: Total Dia of the conductor (mm) | BE4: A1 | BF4: A | BG4: B | BH4: B1 | BI4: C | BJ4: D | BK4: D1 | BL4: D2 | BM4: D3 | BN4: E | BO4: E0 | BP4: E1 | BQ4: E2 | BR4: E3 | BS4: E4 | BT4: E5 | BU4: E6 | BV4: F | BW4: G | BX4: H | BY4: H1 | BZ4: I | CA4: I1 | CB4: I2 | CC4: IA | CD4: J | CE4: K | CF4: L | CG4: L1 | CH4: L2 | CI4: L3 | CJ4: L4 | CK4: L5 | CL4: L6 | CM4: L7 | CN4: L8 | CO4: L9 | CP4: M | CQ4: M1 | CR4: N | CS4: N1 | CT4: N2 | CU4: O | CV4: O1 | CW4: P | CX4: Q | CY4: Q1 | CZ4: Q2 | DA4: Q3 | DB4: Q4 | DC4: Q5 | DD4: Q6 | DE4: Q7 | DF4: Q8 | DG4: R | DH4: R1 | DI4: R2 | DJ4: R1.A | DK4: R2.A | DL4: S | DM4: S.A | DN4: S.B | DO4: S1 | DP4: S1.A | DQ4: T | DR4: T1 | DS4: TA | DT4: T1.A | DU4: U | DW4: A1 | DX4: A | DY4: B | DZ4: B1 | EA4: C | EB4: D | EC4: D1 | ED4: D2 | EE4: D3 | EF4: E | EG4: E0 | EH4: E1 | EI4: E2 | EJ4: E3 | EK4: E4 | EL4: E5 | EM4: E6 | EN4: F | EO4: G | EP4: H | EQ4: H1 | ER4: I | ES4: I1 | ET4: I2 | EU4: IA | EV4: J | EW4: K | EX4: L | EY4: L1 | EZ4: L2 | FA4: L3 | FB4: L4 | FC4: L5 | FD4: L6 | FE4: L7 | FF4: L8 | FG4: L9 | FH4: M | FI4: M1 | FJ4: N | FK4: N1 | FL4: N2 | FM4: O | FN4: O1 | FO4: P | FP4: Q | FQ4: Q1 | FR4: Q2 | FS4: Q3 | FT4: Q4 | FU4: Q5 | FV4: Q6 | FW4: Q7 | FX4: Q8 | FY4: R | FZ4: R1 | GA4: R2 | GB4: R1.A | GC4: R2.A | GD4: S | GE4: S.A | GF4: S.B | GG4: S1 | GH4: S1.A | GI4: T | GJ4: T1 | GK4: TA | GL4: T1.A | GM4: U
D5: MAIN SUBSTATION | G5: VFD | AO5: A
D6: 11kV MV Switchgear-1 | DW6: =IF(BE6=1,($BC6*BE6),0) -> 0 | DX6: =IF(BF6=1,($BC6*BF6),0) -> 0 | DY6: =IF(BG6=1,($BC6*BG6),0) -> 0 | DZ6: =IF(BH6=1,($BC6*BH6),0) -> 0 | EA6: =IF(BI6=1,($BC6*BI6),0) -> 0 | EB6: =IF(BJ6=1,($BC6*BJ6),0) -> 0 | EC6: =IF(BK6=1,($BC6*BK6),0) -> 0 | ED6: =IF(BL6=1,($BC6*BL6),0) -> 0 | ... GM6: =IF(DU6=1,($BC6*DU6),0) -> 0
A7: =A87+1 -> 1 | B7: 1401-B102 | C7: =$D$6 -> 11kV MV Switchgear-1 | D7: START-UP HEATER | E7: AMMONIA PLANT | F7: B | G7: POWER | H7: 3200 | I7: kW | J7: 3Ph | K7: 11000 | L7: 0.85 | M7: 0.95 | N7: =IF(I7="kVA",IF(J7="3Ph",(H7*1000/(1.732*M7*K7)),(H7*1000/(M7*K7))),IF(I7="kW",IF(J7="3Ph",(H7*1000/(1.732*M7*K7*L7)),(H7*1000/(M7*K7*L7))))) -> 208.0017 | O7: =IF(G7="MOTOR",(6*N7),IF(G7="VFD",(1*N7),0)) -> 0 | P7: =IF(G7="MOTOR",0.2,"0.00") -> 0.00 | Q7: 31.5 | R7: 0.16 | S7: =(Q7*1000*SQRT(R7)/94) -> 134.04255 | T7: AIR | U7: 3C | V7: 150 | W7: =CONCATENATE(U7," X ",V7) -> 3C X 150 | X7: =(IF(J7="1Ph",W7,IF(J7="3Ph",(IF(G7="MOTOR",(CONCATENATE(W7,"+PE")),W7))))) -> 3C X 150 | Y7: 6/10(12) | Z7: =IF(T7="AIR",VLOOKUP(W7,'Catalogue Aluminium'!$B$141:$G$173,2,FALSE),IF(T7="GROUND",VLOOKUP(W7,'Catalogue Aluminium'!$B$141:$G$173,3,FALSE),IF(T7="DUCT",VLOOKUP(W7,'Catalogue Aluminium'!$B$141:$G$173,4,FALSE),IF(T7="TRENCH",VLOOKUP(W7,'Catalogue Aluminium'!$B$141:$G$173,2,FALSE))))) -> 309 | AA7: =VLOOKUP(W7,'Catalogue Aluminium'!$B$141:$G$173,5,FALSE) -> 0.265 | AB7: =VLOOKUP(W7,'Catalogue Aluminium'!$B$141:$G$173,6,FALSE) -> 0.093 | AC7: =37+30 -> 67 | AD7: =40+50+38+50+17+(27+77) -> 299 | AE7: =11+8+8+11 -> 38 | AF7: =5+5 -> 10 | AG7: =ROUNDUP(SUM(AC7:AF7)*0.1,0) -> 42 | AH7: =CEILING(SUM(AC7:AG7),10) -> 460 | AI7: =IF(T7="AIR",'Catalogue Aluminium'!$K$141,IF(T7="TRENCH",'Catalogue Aluminium'!$K$144,"NA")) -> 0.82 | AJ7: =IF(T7="Air",(IF(U7="1C",'Catalogue Aluminium'!$L$141,'Catalogue Aluminium'!$M$141)),IF(T7="DUCT",(IF($U7="1C",'Catalogue Aluminium'!$L$142,'Catalogue Aluminium'!$M$142)),IF(T7="GROUND",(IF($U7="1C",'Catalogue Aluminium'!$L$143,'Catalogue Aluminium'!$M$143)),IF(T7="TRENCH",(IF($U7="1C",'Catalogue Aluminium'!$L$144,'Catalogue Aluminium'!$M$144)))))) -> 0.73 | AK7: =IF(T7="Air",'Catalogue Aluminium'!$N$141,IF(T7="GROUND",'Catalogue Aluminium'!$N$142,IF(T7="DUCT",'Catalogue Aluminium'!$N$143,IF(T7="TRENCH",'Catalogue Aluminium'!$N$144,"NA")))) -> NA | AL7: =IF(T7="Air",(IF(U7="1C",'Catalogue Aluminium'!$O$141,'Catalogue Aluminium'!$P$141)),IF(T7="DUCT",(IF($U7="1C",'Catalogue Aluminium'!$O$142,'Catalogue Aluminium'!$P$142)),IF(T7="GROUND",(IF($U7="1C",'Catalogue Aluminium'!$O$143,'Catalogue Aluminium'!$P$143)),IF(T7="TRENCH",(IF($U7="1C",'Catalogue Aluminium'!$O$144,'Catalogue Aluminium'!$P$144)))))) -> NA | AM7: =IF(T7="AIR","NA",IF(T7="TRENCH","NA",IF(T7="DUCT",IF(U7="1C",VLOOKUP(V7,'Catalogue Aluminium'!$Q$142:$S$153,2,FALSE),VLOOKUP(V7,'Catalogue Aluminium'!$Q$142:$S$153,3)),IF(T7="GROUND",IF(U7="1C",VLOOKUP(V7,'Catalogue Aluminium'!$Q$142:$S$153,2,FALSE),VLOOKUP(V7,'Catalogue Aluminium'!$Q$142:$S$153,3)))))) -> NA | AN7: =IF(T7="AIR",AI7*AJ7,IF(T7="TRENCH",AI7*AJ7,IF(T7="DUCT",AJ7*AK7*AL7*AM7,IF(T7="GROUND",AJ7*AK7*AL7*AM7)))) -> 0.5986 | AO7: =Z7*AN7 -> 184.9674 | AP7: =CEILING(((N7)/AO7),1) -> 2 | AQ7: =IF(AO7*AP7>=N7,"YES","NO") -> YES | AR7: =SQRT(3)*AH7*N7*((AA7*L7)+(AB7*SIN(ACOS(L7))))*100/(AP7*K7*1000) -> 0.20658306 | AS7: =IF(G7="INCOMER",(IF(AR7<=2,"YES","NO")),IF(G7="POWER",(IF(AR7<=2.5,"YES","NO")),IF(G7="MOTOR",(IF(AR7<=3,"YES","NO"))))) -> YES | AT7: =IF(G7="MOTOR",(SQRT(3)*AH7*O7*((AA7*P7)+(AB7*SIN(ACOS(P7))))*100/(AP7*K7*1000)),"NA") -> NA | AU7: =IF(G7="MOTOR",IF(AT7<=15,"YES","NO"),"NA") -> NA | AV7: =IF(U7="1C",CONCATENATE(AP7,"R x ",Y7,"kV x ",U7," x ",V7," Sqmm/Phase"),CONCATENATE(AP7,"R x ","6/10 (12)kV x ",U7," x ",V7," Sqmm")) -> 2R x 6/10 (12)kV x 3C x 150 Sqmm | AW7: =IF(U7="1C",CONCATENATE(AP7,"R x ",Y7,"kV x ",U7," x ",V7," Sqmm/Phase"),CONCATENATE(AP7,"R x ","6/10 (12)kV x ",U7," x ",V7," Sqmm")) -> 2R x 6/10 (12)kV x 3C x 150 Sqmm | AX7: =IF(U7="1C",(3*AH7*AP7),(AH7*AP7)) -> 920 | AZ7: =IF(U7="1C",(3*AP7*2),(AP7*2)) -> 4 | BA7: =CONCATENATE(IF(BE7=1,BE$4,""),IF(BF7=1,BF$4,""),IF(BG7=1,BG$4,""),IF(BH7=1,BH$4,""),IF(BI7=1,BI$4,""),IF(BJ7=1,BJ$4,""),IF(BK7=1,BK$4,""),IF(BL7=1,BL$4,""),IF(BM7=1,BM$4,""),IF(BN7=1,BN$4,""),IF(BO7=1,BO$4,""),IF(BP7=1,BP$4,""),IF(BQ7=1,BQ$4,""),IF(BR7=1,BR$4,""),IF(BS7=1,BS$4,""),IF(BT7=1,BT$4,""),IF(BU7=1,BU$4,""),IF(BV7=1,BV$4,""),IF(BW7=1,BW$4,""),IF(BX7=1,BX$4,""),IF(BY7=1,BY$4,""),IF(BZ7=1,BZ$4,""),IF(CA7=1,CA$4,""),IF(CB7=1,CB$4,""),IF(CC7=1,CC$4,""),IF(CD7=1,CD$4,""),IF(CE7=1,CE$4,""),IF(CF7=1,CF$4,""),IF(CG7=1,CG$4,""),IF(CH7=1,CH$4,""),IF(CI7=1,CI$4,""),IF(CJ7=1,CJ$4,""),IF(CK7=1,CK$4,""),IF(CL7=1,CL$4,""),IF(CM7=1,CM$4,""),IF(CN7=1,CN$4,""),IF(CO7=1,CO$4,""),IF(CP7=1,CP$4,""),IF(CQ7=1,CQ$4,""),IF(CR7=1,CR$4,""),IF(CS7=1,CS$4,""),IF(CT7=1,CT$4,""),IF(CU7=1,CU$4,""),IF(CV7=1,CV$4,""),IF(CW7=1,CW$4,""),IF(CX7=1,CX$4,""),IF(CY7=1,CY$4,""),IF(CZ7=1,CZ$4,""),IF(DA7=1,DA$4,""),IF(DB7=1,DB$4,""),IF(DC7=1,DC$4,""),IF(DD7=1,DD$4,""),IF(DE7=1,DE$4,""),IF(DF7=1,DF$4,""),IF(DG7=1,DG$4,""),IF(DH7=1,DH$4,""),IF(DI7=1,DI$4,""),IF(DJ7=1,DJ$4,""),IF(DK7=1,DK$4,""),IF(DL7=1,DL$4,""),IF(DM7=1,DM$4,""),IF(DN7=1,DN$4,""),IF(DO7=1,DO$4,""),IF(DP7=1,DP$4,""),IF(DQ7=1,DQ$4,""),IF(DR7=1,DR$4,""),IF(DS7=1,DS$4,""),IF(DT7=1,DT$4,""),IF(DU7=1,DU$4,"")) -> ACDEE1E2E3 | BB7: =VLOOKUP(W7,'Catalogue Aluminium'!$B$141:$H$173,7,FALSE) -> 62 | BC7: =AP7*BB7 -> 124 | BF7: 1 | BI7: 1 | BJ7: 1 | BN7: 1 | BP7: 1 | BQ7: 1 | BR7: 1 | DW7: =IF(BE7=1,($BC7*BE7),0) -> 0 | DX7: =IF(BF7=1,($BC7*BF7),0) -> 124 | DY7: =IF(BG7=1,($BC7*BG7),0) -> 0 | DZ7: =IF(BH7=1,($BC7*BH7),0) -> 0 | EA7: =IF(BI7=1,($BC7*BI7),0) -> 124 | EB7: =IF(BJ7=1,($BC7*BJ7),0) -> 124 | EC7: =IF(BK7=1,($BC7*BK7),0) -> 0 | ED7: =IF(BL7=1,($BC7*BL7),0) -> 0 | ... GM7: =IF(DU7=1,($BC7*DU7),0) -> 0
A8: X | B8: 1418-P003A | C8: =$D$6 -> 11kV MV Switchgear-1 | D8: MAIN FIRE PUMP-1 | E8: FIRE WATER PUMP HOUSE | F8: A | G8: MOTOR | H8: 500 | I8: kW | J8: 3Ph | K8: 11000 | L8: 0.87 | M8: 0.955 | N8: =IF(I8="kVA",IF(J8="3Ph",(H8*1000/(1.732*M8*K8)),(H8*1000/(M8*K8))),IF(I8="kW",IF(J8="3Ph",(H8*1000/(1.732*M8*K8*L8)),(H8*1000/(M8*K8*L8))))) -> 31.586886 | O8: =IF(G8="MOTOR",(6*N8),IF(G8="VFD",(1*N8),0)) -> 189.52131 | P8: =IF(G8="MOTOR",0.2,"0.00") -> 0.2 | Q8: 31.5 | R8: 0.16 | S8: =(Q8*1000*SQRT(R8)/94) -> 134.04255 | T8: AIR | U8: 3C | V8: 150 | W8: =CONCATENATE(U8," X ",V8) -> 3C X 150 | X8: =(IF(J8="1Ph",W8,IF(J8="3Ph",(IF(G8="MOTOR",(CONCATENATE(W8,"+PE")),W8))))) -> 3C X 150+PE | Y8: 6/10(12) | Z8: =IF(T8="AIR",VLOOKUP(W8,'Catalogue Aluminium'!$B$141:$G$173,2,FALSE),IF(T8="GROUND",VLOOKUP(W8,'Catalogue Aluminium'!$B$141:$G$173,3,FALSE),IF(T8="DUCT",VLOOKUP(W8,'Catalogue Aluminium'!$B$141:$G$173,4,FALSE),IF(T8="TRENCH",VLOOKUP(W8,'Catalogue Aluminium'!$B$141:$G$173,2,FALSE))))) -> 309 | AA8: =VLOOKUP(W8,'Catalogue Aluminium'!$B$141:$G$173,5,FALSE) -> 0.265 | AB8: =VLOOKUP(W8,'Catalogue Aluminium'!$B$141:$G$173,6,FALSE) -> 0.093 | AC8: =18+30 -> 48 | AD8: =11+34+48+35+30+51+5 -> 214 | AE8: 20 | AF8: 6 | AG8: =ROUNDUP(SUM(AC8:AF8)*0.1,0) -> 29 | AH8: =CEILING(SUM(AC8:AG8),10) -> 320 | AI8: =IF(T8="AIR",'Catalogue Aluminium'!$K$141,IF(T8="TRENCH",'Catalogue Aluminium'!$K$144,"NA")) -> 0.82 | AJ8: =IF(T8="Air",(IF(U8="1C",'Catalogue Aluminium'!$L$141,'Catalogue Aluminium'!$M$141)),IF(T8="DUCT",(IF($U8="1C",'Catalogue Aluminium'!$L$142,'Catalogue Aluminium'!$M$142)),IF(T8="GROUND",(IF($U8="1C",'Catalogue Aluminium'!$L$143,'Catalogue Aluminium'!$M$143)),IF(T8="TRENCH",(IF($U8="1C",'Catalogue Aluminium'!$L$144,'Catalogue Aluminium'!$M$144)))))) -> 0.73 | AK8: =IF(T8="Air",'Catalogue Aluminium'!$N$141,IF(T8="GROUND",'Catalogue Aluminium'!$N$142,IF(T8="DUCT",'Catalogue Aluminium'!$N$143,IF(T8="TRENCH",'Catalogue Aluminium'!$N$144,"NA")))) -> NA | AL8: =IF(T8="Air",(IF(U8="1C",'Catalogue Aluminium'!$O$141,'Catalogue Aluminium'!$P$141)),IF(T8="DUCT",(IF($U8="1C",'Catalogue Aluminium'!$O$142,'Catalogue Aluminium'!$P$142)),IF(T8="GROUND",(IF($U8="1C",'Catalogue Aluminium'!$O$143,'Catalogue Aluminium'!$P$143)),IF(T8="TRENCH",(IF($U8="1C",'Catalogue Aluminium'!$O$144,'Catalogue Aluminium'!$P$144)))))) -> NA | AM8: =IF(T8="AIR","NA",IF(T8="TRENCH","NA",IF(T8="DUCT",IF(U8="1C",VLOOKUP(V8,'Catalogue Aluminium'!$Q$142:$S$153,2,FALSE),VLOOKUP(V8,'Catalogue Aluminium'!$Q$142:$S$153,3)),IF(T8="GROUND",IF(U8="1C",VLOOKUP(V8,'Catalogue Aluminium'!$Q$142:$S$153,2,FALSE),VLOOKUP(V8,'Catalogue Aluminium'!$Q$142:$S$153,3)))))) -> NA | AN8: =IF(T8="AIR",AI8*AJ8,IF(T8="TRENCH",AI8*AJ8,IF(T8="DUCT",AJ8*AK8*AL8*AM8,IF(T8="GROUND",AJ8*AK8*AL8*AM8)))) -> 0.5986 | AO8: =Z8*AN8 -> 184.9674 | AP8: =CEILING(((N8)/AO8),1) -> 1 | AQ8: =IF(AO8*AP8>=N8,"YES","NO") -> YES | AR8: =SQRT(3)*AH8*N8*((AA8*L8)+(AB8*SIN(ACOS(L8))))*100/(AP8*K8*1000) -> 0.043991498 | AS8: =IF(G8="INCOMER",(IF(AR8<=2,"YES","NO")),IF(G8="POWER",(IF(AR8<=2,"YES","NO")),IF(G8="MOTOR",(IF(AR8<=3,"YES","NO"))))) -> YES | AT8: =IF(G8="MOTOR",(SQRT(3)*AH8*O8*((AA8*P8)+(AB8*SIN(ACOS(P8))))*100/(AP8*K8*1000)),"NA") -> 0.13762689 | AU8: =IF(G8="MOTOR",IF(AT8<=15,"YES","NO"),"NA") -> YES | AV8: =IF(U8="1C",CONCATENATE(AP8,"R x ",Y8,"kV x ",U8," x ",V8," Sqmm/Phase"),CONCATENATE(AP8,"R x ","6/10 (12)kV x ",U8," x ",V8," Sqmm")) -> 1R x 6/10 (12)kV x 3C x 150 Sqmm | AW8: =IF(U8="1C",CONCATENATE(AP8,"R x ",Y8,"kV x ",U8," x ",V8," Sqmm/Phase"),CONCATENATE(AP8,"R x ","6/10 (12)kV x ",U8," x ",V8," Sqmm")) -> 1R x 6/10 (12)kV x 3C x 150 Sqmm | BA8: =CONCATENATE(IF(BE8=1,BE$4,""),IF(BF8=1,BF$4,""),IF(BG8=1,BG$4,""),IF(BH8=1,BH$4,""),IF(BI8=1,BI$4,""),IF(BJ8=1,BJ$4,""),IF(BK8=1,BK$4,""),IF(BL8=1,BL$4,""),IF(BM8=1,BM$4,""),IF(BN8=1,BN$4,""),IF(BO8=1,BO$4,""),IF(BP8=1,BP$4,""),IF(BQ8=1,BQ$4,""),IF(BR8=1,BR$4,""),IF(BS8=1,BS$4,""),IF(BT8=1,BT$4,""),IF(BU8=1,BU$4,""),IF(BV8=1,BV$4,""),IF(BW8=1,BW$4,""),IF(BX8=1,BX$4,""),IF(BY8=1,BY$4,""),IF(BZ8=1,BZ$4,""),IF(CA8=1,CA$4,""),IF(CB8=1,CB$4,""),IF(CC8=1,CC$4,""),IF(CD8=1,CD$4,""),IF(CE8=1,CE$4,""),IF(CF8=1,CF$4,""),IF(CG8=1,CG$4,""),IF(CH8=1,CH$4,""),IF(CI8=1,CI$4,""),IF(CJ8=1,CJ$4,""),IF(CK8=1,CK$4,""),IF(CL8=1,CL$4,""),IF(CM8=1,CM$4,""),IF(CN8=1,CN$4,""),IF(CO8=1,CO$4,""),IF(CP8=1,CP$4,""),IF(CQ8=1,CQ$4,""),IF(CR8=1,CR$4,""),IF(CS8=1,CS$4,""),IF(CT8=1,CT$4,""),IF(CU8=1,CU$4,""),IF(CV8=1,CV$4,""),IF(CW8=1,CW$4,""),IF(CX8=1,CX$4,""),IF(CY8=1,CY$4,""),IF(CZ8=1,CZ$4,""),IF(DA8=1,DA$4,""),IF(DB8=1,DB$4,""),IF(DC8=1,DC$4,""),IF(DD8=1,DD$4,""),IF(DE8=1,DE$4,""),IF(DF8=1,DF$4,""),IF(DG8=1,DG$4,""),IF(DH8=1,DH$4,""),IF(DI8=1,DI$4,""),IF(DJ8=1,DJ$4,""),IF(DK8=1,DK$4,""),IF(DL8=1,DL$4,""),IF(DM8=1,DM$4,""),IF(DN8=1,DN$4,""),IF(DO8=1,DO$4,""),IF(DP8=1,DP$4,""),IF(DQ8=1,DQ$4,""),IF(DR8=1,DR$4,""),IF(DS8=1,DS$4,""),IF(DT8=1,DT$4,""),IF(DU8=1,DU$4,"")) | DW8: =IF(BE8=1,($BC8*BE8),0) -> 0 | DX8: =IF(BF8=1,($BC8*BF8),0) -> 0 | DY8: =IF(BG8=1,($BC8*BG8),0) -> 0 | DZ8: =IF(BH8=1,($BC8*BH8),0) -> 0 | EA8: =IF(BI8=1,($BC8*BI8),0) -> 0 | EB8: =IF(BJ8=1,($BC8*BJ8),0) -> 0 | EC8: =IF(BK8=1,($BC8*BK8),0) -> 0 | ED8: =IF(BL8=1,($BC8*BL8),0) -> 0 | ... FT8: =IF(DB8=1,($BC8*DB8),0) -> 0 | FY8: =IF(DG8=1,($BC8*DG8),0) -> 0 | FZ8: =IF(DH8=1,($BC8*DH8),0) -> 0 | GA8: =IF(DI8=1,($BC8*DI8),0) -> 0 | GB8: =IF(DJ8=1,($BC8*DJ8),0) -> 0 | GC8: =IF(DK8=1,($BC8*DK8),0) -> 0 | GD8: =IF(DL8=1,($BC8*DL8),0) -> 0 | GE8: =IF(DM8=1,($BC8*DM8),0) -> 0 | GF8: =IF(DN8=1,($BC8*DN8),0) -> 0 | ... GM8: =IF(DU8=1,($BC8*DU8),0) -> 0
A9: X | B9: 1418-P003B | C9: =$D$6 -> 11kV MV Switchgear-1 | D9: MAIN FIRE PUMP-2 | E9: FIRE WATER PUMP HOUSE | F9: B | G9: MOTOR | H9: 500 | I9: kW | J9: 3Ph | K9: 11000 | L9: 0.87 | M9: 0.955 | N9: =IF(I9="kVA",IF(J9="3Ph",(H9*1000/(1.732*M9*K9)),(H9*1000/(M9*K9))),IF(I9="kW",IF(J9="3Ph",(H9*1000/(1.732*M9*K9*L9)),(H9*1000/(M9*K9*L9))))) -> 31.586886 | O9: =IF(G9="MOTOR",(6*N9),IF(G9="VFD",(1*N9),0)) -> 189.52131 | P9: =IF(G9="MOTOR",0.2,"0.00") -> 0.2 | Q9: 31.5 | R9: 0.16 | S9: =(Q9*1000*SQRT(R9)/94) -> 134.04255 | T9: AIR | U9: 3C | V9: 150 | W9: =CONCATENATE(U9," X ",V9) -> 3C X 150 | X9: =(IF(J9="1Ph",W9,IF(J9="3Ph",(IF(G9="MOTOR",(CONCATENATE(W9,"+PE")),W9))))) -> 3C X 150+PE | Y9: 6/10(12) | Z9: =IF(T9="AIR",VLOOKUP(W9,'Catalogue Aluminium'!$B$141:$G$173,2,FALSE),IF(T9="GROUND",VLOOKUP(W9,'Catalogue Aluminium'!$B$141:$G$173,3,FALSE),IF(T9="DUCT",VLOOKUP(W9,'Catalogue Aluminium'!$B$141:$G$173,4,FALSE),IF(T9="TRENCH",VLOOKUP(W9,'Catalogue Aluminium'!$B$141:$G$173,2,FALSE))))) -> 309 | AA9: =VLOOKUP(W9,'Catalogue Aluminium'!$B$141:$G$173,5,FALSE) -> 0.265 | AB9: =VLOOKUP(W9,'Catalogue Aluminium'!$B$141:$G$173,6,FALSE) -> 0.093 | AC9: =19+30 -> 49 | AD9: =11+34+48+35+30+51+5 -> 214 | AE9: 20 | AF9: 6 | AG9: =ROUNDUP(SUM(AC9:AF9)*0.1,0) -> 29 | AH9: =CEILING(SUM(AC9:AG9),10) -> 320 | AI9: =IF(T9="AIR",'Catalogue Aluminium'!$K$141,IF(T9="TRENCH",'Catalogue Aluminium'!$K$144,"NA")) -> 0.82 | AJ9: =IF(T9="Air",(IF(U9="1C",'Catalogue Aluminium'!$L$141,'Catalogue Aluminium'!$M$141)),IF(T9="DUCT",(IF($U9="1C",'Catalogue Aluminium'!$L$142,'Catalogue Aluminium'!$M$142)),IF(T9="GROUND",(IF($U9="1C",'Catalogue Aluminium'!$L$143,'Catalogue Aluminium'!$M$143)),IF(T9="TRENCH",(IF($U9="1C",'Catalogue Aluminium'!$L$144,'Catalogue Aluminium'!$M$144)))))) -> 0.73 | AK9: =IF(T9="Air",'Catalogue Aluminium'!$N$141,IF(T9="GROUND",'Catalogue Aluminium'!$N$142,IF(T9="DUCT",'Catalogue Aluminium'!$N$143,IF(T9="TRENCH",'Catalogue Aluminium'!$N$144,"NA")))) -> NA | AL9: =IF(T9="Air",(IF(U9="1C",'Catalogue Aluminium'!$O$141,'Catalogue Aluminium'!$P$141)),IF(T9="DUCT",(IF($U9="1C",'Catalogue Aluminium'!$O$142,'Catalogue Aluminium'!$P$142)),IF(T9="GROUND",(IF($U9="1C",'Catalogue Aluminium'!$O$143,'Catalogue Aluminium'!$P$143)),IF(T9="TRENCH",(IF($U9="1C",'Catalogue Aluminium'!$O$144,'Catalogue Aluminium'!$P$144)))))) -> NA | AM9: =IF(T9="AIR","NA",IF(T9="TRENCH","NA",IF(T9="DUCT",IF(U9="1C",VLOOKUP(V9,'Catalogue Aluminium'!$Q$142:$S$153,2,FALSE),VLOOKUP(V9,'Catalogue Aluminium'!$Q$142:$S$153,3)),IF(T9="GROUND",IF(U9="1C",VLOOKUP(V9,'Catalogue Aluminium'!$Q$142:$S$153,2,FALSE),VLOOKUP(V9,'Catalogue Aluminium'!$Q$142:$S$153,3)))))) -> NA | AN9: =IF(T9="AIR",AI9*AJ9,IF(T9="TRENCH",AI9*AJ9,IF(T9="DUCT",AJ9*AK9*AL9*AM9,IF(T9="GROUND",AJ9*AK9*AL9*AM9)))) -> 0.5986 | AO9: =Z9*AN9 -> 184.9674 | AP9: =CEILING(((N9)/AO9),1) -> 1 | AQ9: =IF(AO9*AP9>=N9,"YES","NO") -> YES | AR9: =SQRT(3)*AH9*N9*((AA9*L9)+(AB9*SIN(ACOS(L9))))*100/(AP9*K9*1000) -> 0.043991498 | AS9: =IF(G9="INCOMER",(IF(AR9<=2,"YES","NO")),IF(G9="POWER",(IF(AR9<=2,"YES","NO")),IF(G9="MOTOR",(IF(AR9<=3,"YES","NO"))))) -> YES | AT9: =IF(G9="MOTOR",(SQRT(3)*AH9*O9*((AA9*P9)+(AB9*SIN(ACOS(P9))))*100/(AP9*K9*1000)),"NA") -> 0.13762689 | AU9: =IF(G9="MOTOR",IF(AT9<=15,"YES","NO"),"NA") -> YES | AV9: =IF(U9="1C",CONCATENATE(AP9,"R x ",Y9,"kV x ",U9," x ",V9," Sqmm/Phase"),CONCATENATE(AP9,"R x ","6/10 (12)kV x ",U9," x ",V9," Sqmm")) -> 1R x 6/10 (12)kV x 3C x 150 Sqmm | AW9: =IF(U9="1C",CONCATENATE(AP9,"R x ",Y9,"kV x ",U9," x ",V9," Sqmm/Phase"),CONCATENATE(AP9,"R x ","6/10 (12)kV x ",U9," x ",V9," Sqmm")) -> 1R x 6/10 (12)kV x 3C x 150 Sqmm | BA9: =CONCATENATE(IF(BE9=1,BE$4,""),IF(BF9=1,BF$4,""),IF(BG9=1,BG$4,""),IF(BH9=1,BH$4,""),IF(BI9=1,BI$4,""),IF(BJ9=1,BJ$4,""),IF(BK9=1,BK$4,""),IF(BL9=1,BL$4,""),IF(BM9=1,BM$4,""),IF(BN9=1,BN$4,""),IF(BO9=1,BO$4,""),IF(BP9=1,BP$4,""),IF(BQ9=1,BQ$4,""),IF(BR9=1,BR$4,""),IF(BS9=1,BS$4,""),IF(BT9=1,BT$4,""),IF(BU9=1,BU$4,""),IF(BV9=1,BV$4,""),IF(BW9=1,BW$4,""),IF(BX9=1,BX$4,""),IF(BY9=1,BY$4,""),IF(BZ9=1,BZ$4,""),IF(CA9=1,CA$4,""),IF(CB9=1,CB$4,""),IF(CC9=1,CC$4,""),IF(CD9=1,CD$4,""),IF(CE9=1,CE$4,""),IF(CF9=1,CF$4,""),IF(CG9=1,CG$4,""),IF(CH9=1,CH$4,""),IF(CI9=1,CI$4,""),IF(CJ9=1,CJ$4,""),IF(CK9=1,CK$4,""),IF(CL9=1,CL$4,""),IF(CM9=1,CM$4,""),IF(CN9=1,CN$4,""),IF(CO9=1,CO$4,""),IF(CP9=1,CP$4,""),IF(CQ9=1,CQ$4,""),IF(CR9=1,CR$4,""),IF(CS9=1,CS$4,""),IF(CT9=1,CT$4,""),IF(CU9=1,CU$4,""),IF(CV9=1,CV$4,""),IF(CW9=1,CW$4,""),IF(CX9=1,CX$4,""),IF(CY9=1,CY$4,""),IF(CZ9=1,CZ$4,""),IF(DA9=1,DA$4,""),IF(DB9=1,DB$4,""),IF(DC9=1,DC$4,""),IF(DD9=1,DD$4,""),IF(DE9=1,DE$4,""),IF(DF9=1,DF$4,""),IF(DG9=1,DG$4,""),IF(DH9=1,DH$4,""),IF(DI9=1,DI$4,""),IF(DJ9=1,DJ$4,""),IF(DK9=1,DK$4,""),IF(DL9=1,DL$4,""),IF(DM9=1,DM$4,""),IF(DN9=1,DN$4,""),IF(DO9=1,DO$4,""),IF(DP9=1,DP$4,""),IF(DQ9=1,DQ$4,""),IF(DR9=1,DR$4,""),IF(DS9=1,DS$4,""),IF(DT9=1,DT$4,""),IF(DU9=1,DU$4,"")) | DW9: =IF(BE9=1,($BC9*BE9),0) -> 0 | DX9: =IF(BF9=1,($BC9*BF9),0) -> 0 | DY9: =IF(BG9=1,($BC9*BG9),0) -> 0 | DZ9: =IF(BH9=1,($BC9*BH9),0) -> 0 | EA9: =IF(BI9=1,($BC9*BI9),0) -> 0 | EB9: =IF(BJ9=1,($BC9*BJ9),0) -> 0 | EC9: =IF(BK9=1,($BC9*BK9),0) -> 0 | ED9: =IF(BL9=1,($BC9*BL9),0) -> 0 | ... FT9: =IF(DB9=1,($BC9*DB9),0) -> 0 | FY9: =IF(DG9=1,($BC9*DG9),0) -> 0 | FZ9: =IF(DH9=1,($BC9*DH9),0) -> 0 | GA9: =IF(DI9=1,($BC9*DI9),0) -> 0 | GB9: =IF(DJ9=1,($BC9*DJ9),0) -> 0 | GC9: =IF(DK9=1,($BC9*DK9),0) -> 0 | GD9: =IF(DL9=1,($BC9*DL9),0) -> 0 | GE9: =IF(DM9=1,($BC9*DM9),0) -> 0 | GF9: =IF(DN9=1,($BC9*DN9),0) -> 0 | ... GM9: =IF(DU9=1,($BC9*DU9),0) -> 0
A10: =A7+1 -> 2 | B10: 1402-P002A | C10: =$D$6 -> 11kV MV Switchgear-1 | D10: AMMONIA TRANSFER PUMP | E10: AMMONIA STORAGE AREA | F10: A | G10: MOTOR | H10: 355 | I10: kW | J10: 3Ph | K10: 11000 | L10: 0.86 | M10: 0.964 | N10: =IF(I10="kVA",IF(J10="3Ph",(H10*1000/(1.732*M10*K10)),(H10*1000/(M10*K10))),IF(I10="kW",IF(J10="3Ph",(H10*1000/(1.732*M10*K10*L10)),(H10*1000/(M10*K10*L10))))) -> 22.475652 | O10: =IF(G10="MOTOR",(6*N10),IF(G10="VFD",(1*N10),0)) -> 134.85391 | P10: =IF(G10="MOTOR",0.2,"0.00") -> 0.2 | Q10: 31.5 | R10: 0.16 | S10: =(Q10*1000*SQRT(R10)/94) -> 134.04255 | T10: AIR | U10: 3C | V10: 150 | W10: =CONCATENATE(U10," X ",V10) -> 3C X 150 | X10: =(IF(J10="1Ph",W10,IF(J10="3Ph",(IF(G10="MOTOR",(CONCATENATE(W10,"+PE")),W10))))) -> 3C X 150+PE | Y10: 6/10(12) | Z10: =IF(T10="AIR",VLOOKUP(W10,'Catalogue Aluminium'!$B$141:$G$173,2,FALSE),IF(T10="GROUND",VLOOKUP(W10,'Catalogue Aluminium'!$B$141:$G$173,3,FALSE),IF(T10="DUCT",VLOOKUP(W10,'Catalogue Aluminium'!$B$141:$G$173,4,FALSE),IF(T10="TRENCH",VLOOKUP(W10,'Catalogue Aluminium'!$B$141:$G$173,2,FALSE))))) -> 309 | AA10: =VLOOKUP(W10,'Catalogue Aluminium'!$B$141:$G$173,5,FALSE) -> 0.265 | AB10: =VLOOKUP(W10,'Catalogue Aluminium'!$B$141:$G$173,6,FALSE) -> 0.093 | AC10: =37+30 -> 67 | AD10: =40+50+38+50+58+60+20+31+47 -> 394 | AE10: =11+8+3+10+10 -> 42 | AF10: =5+5 -> 10 | AG10: =ROUNDUP(SUM(AC10:AF10)*0.1,0) -> 52 | AH10: =CEILING(SUM(AC10:AG10),10) -> 570 | AI10: =IF(T10="AIR",'Catalogue Aluminium'!$K$141,IF(T10="TRENCH",'Catalogue Aluminium'!$K$144,"NA")) -> 0.82 | AJ10: =IF(T10="Air",(IF(U10="1C",'Catalogue Aluminium'!$L$141,'Catalogue Aluminium'!$M$141)),IF(T10="DUCT",(IF($U10="1C",'Catalogue Aluminium'!$L$142,'Catalogue Aluminium'!$M$142)),IF(T10="GROUND",(IF($U10="1C",'Catalogue Aluminium'!$L$143,'Catalogue Aluminium'!$M$143)),IF(T10="TRENCH",(IF($U10="1C",'Catalogue Aluminium'!$L$144,'Catalogue Aluminium'!$M$144)))))) -> 0.73 | AK10: =IF(T10="Air",'Catalogue Aluminium'!$N$141,IF(T10="GROUND",'Catalogue Aluminium'!$N$142,IF(T10="DUCT",'Catalogue Aluminium'!$N$143,IF(T10="TRENCH",'Catalogue Aluminium'!$N$144,"NA")))) -> NA | AL10: =IF(T10="Air",(IF(U10="1C",'Catalogue Aluminium'!$O$141,'Catalogue Aluminium'!$P$141)),IF(T10="DUCT",(IF($U10="1C",'Catalogue Aluminium'!$O$142,'Catalogue Aluminium'!$P$142)),IF(T10="GROUND",(IF($U10="1C",'Catalogue Aluminium'!$O$143,'Catalogue Aluminium'!$P$143)),IF(T10="TRENCH",(IF($U10="1C",'Catalogue Aluminium'!$O$144,'Catalogue Aluminium'!$P$144)))))) -> NA | AM10: =IF(T10="AIR","NA",IF(T10="TRENCH","NA",IF(T10="DUCT",IF(U10="1C",VLOOKUP(V10,'Catalogue Aluminium'!$Q$142:$S$153,2,FALSE),VLOOKUP(V10,'Catalogue Aluminium'!$Q$142:$S$153,3)),IF(T10="GROUND",IF(U10="1C",VLOOKUP(V10,'Catalogue Aluminium'!$Q$142:$S$153,2,FALSE),VLOOKUP(V10,'Catalogue Aluminium'!$Q$142:$S$153,3)))))) -> NA | AN10: =IF(T10="AIR",AI10*AJ10,IF(T10="TRENCH",AI10*AJ10,IF(T10="DUCT",AJ10*AK10*AL10*AM10,IF(T10="GROUND",AJ10*AK10*AL10*AM10)))) -> 0.5986 | AO10: =Z10*AN10 -> 184.9674 | AP10: =CEILING(((N10)/AO10),1) -> 1 | AQ10: =IF(AO10*AP10>=N10,"YES","NO") -> YES | AR10: =SQRT(3)*AH10*N10*((AA10*L10)+(AB10*SIN(ACOS(L10))))*100/(AP10*K10*1000) -> 0.055545868 | AS10: =IF(G10="INCOMER",(IF(AR10<=2,"YES","NO")),IF(G10="POWER",(IF(AR10<=2.5,"YES","NO")),IF(G10="MOTOR",(IF(AR10<=3,"YES","NO"))))) -> YES | AT10: =IF(G10="MOTOR",(SQRT(3)*AH10*O10*((AA10*P10)+(AB10*SIN(ACOS(P10))))*100/(AP10*K10*1000)),"NA") -> 0.17443501 | AU10: =IF(G10="MOTOR",IF(AT10<=15,"YES","NO"),"NA") -> YES | AV10: =IF(U10="1C",CONCATENATE(AP10,"R x ",Y10,"kV x ",U10," x ",V10," Sqmm/Phase"),CONCATENATE(AP10,"R x ","6/10 (12)kV x ",U10," x ",V10," Sqmm")) -> 1R x 6/10 (12)kV x 3C x 150 Sqmm | AW10: =IF(U10="1C",CONCATENATE(AP10,"R x ",Y10,"kV x ",U10," x ",V10," Sqmm/Phase"),CONCATENATE(AP10,"R x ","6/10 (12)kV x ",U10," x ",V10," Sqmm")) -> 1R x 6/10 (12)kV x 3C x 150 Sqmm | AX10: =IF(U10="1C",(3*AH10*AP10),(AH10*AP10)) -> 570 | AZ10: =IF(U10="1C",(3*AP10*2),(AP10*2)) -> 2 | BA10: =CONCATENATE(IF(BE10=1,BE$4,""),IF(BF10=1,BF$4,""),IF(BG10=1,BG$4,""),IF(BH10=1,BH$4,""),IF(BI10=1,BI$4,""),IF(BJ10=1,BJ$4,""),IF(BK10=1,BK$4,""),IF(BL10=1,BL$4,""),IF(BM10=1,BM$4,""),IF(BN10=1,BN$4,""),IF(BO10=1,BO$4,""),IF(BP10=1,BP$4,""),IF(BQ10=1,BQ$4,""),IF(BR10=1,BR$4,""),IF(BS10=1,BS$4,""),IF(BT10=1,BT$4,""),IF(BU10=1,BU$4,""),IF(BV10=1,BV$4,""),IF(BW10=1,BW$4,""),IF(BX10=1,BX$4,""),IF(BY10=1,BY$4,""),IF(BZ10=1,BZ$4,""),IF(CA10=1,CA$4,""),IF(CB10=1,CB$4,""),IF(CC10=1,CC$4,""),IF(CD10=1,CD$4,""),IF(CE10=1,CE$4,""),IF(CF10=1,CF$4,""),IF(CG10=1,CG$4,""),IF(CH10=1,CH$4,""),IF(CI10=1,CI$4,""),IF(CJ10=1,CJ$4,""),IF(CK10=1,CK$4,""),IF(CL10=1,CL$4,""),IF(CM10=1,CM$4,""),IF(CN10=1,CN$4,""),IF(CO10=1,CO$4,""),IF(CP10=1,CP$4,""),IF(CQ10=1,CQ$4,""),IF(CR10=1,CR$4,""),IF(CS10=1,CS$4,""),IF(CT10=1,CT$4,""),IF(CU10=1,CU$4,""),IF(CV10=1,CV$4,""),IF(CW10=1,CW$4,""),IF(CX10=1,CX$4,""),IF(CY10=1,CY$4,""),IF(CZ10=1,CZ$4,""),IF(DA10=1,DA$4,""),IF(DB10=1,DB$4,""),IF(DC10=1,DC$4,""),IF(DD10=1,DD$4,""),IF(DE10=1,DE$4,""),IF(DF10=1,DF$4,""),IF(DG10=1,DG$4,""),IF(DH10=1,DH$4,""),IF(DI10=1,DI$4,""),IF(DJ10=1,DJ$4,""),IF(DK10=1,DK$4,""),IF(DL10=1,DL$4,""),IF(DM10=1,DM$4,""),IF(DN10=1,DN$4,""),IF(DO10=1,DO$4,""),IF(DP10=1,DP$4,""),IF(DQ10=1,DQ$4,""),IF(DR10=1,DR$4,""),IF(DS10=1,DS$4,""),IF(DT10=1,DT$4,""),IF(DU10=1,DU$4,"")) -> ACDEFGIJ | BB10: =VLOOKUP(W10,'Catalogue Aluminium'!$B$141:$H$173,7,FALSE) -> 62 | BC10: =AP10*BB10 -> 62 | BF10: 1 | BI10: 1 | BJ10: 1 | BN10: 1 | BV10: 1 | BW10: 1 | BZ10: 1 | CD10: 1 | DW10: =IF(BE10=1,($BC10*BE10),0) -> 0 | DX10: =IF(BF10=1,($BC10*BF10),0) -> 62 | DY10: =IF(BG10=1,($BC10*BG10),0) -> 0 | DZ10: =IF(BH10=1,($BC10*BH10),0) -> 0 | EA10: =IF(BI10=1,($BC10*BI10),0) -> 62 | EB10: =IF(BJ10=1,($BC10*BJ10),0) -> 62 | EC10: =IF(BK10=1,($BC10*BK10),0) -> 0 | ED10: =IF(BL10=1,($BC10*BL10),0) -> 0 | ... GM10: =IF(DU10=1,($BC10*DU10),0) -> 0
A11: =A10+1 -> 3 | B11: 1402-P002A | C11: =$D$6 -> 11kV MV Switchgear-1 | D11: AMMONIA TRANSFER PUMP-SPACE HEATER | E11: AMMONIA STORAGE AREA | F11: A | G11: POWER | H11: 0.15 | I11: kW | J11: 1Ph | K11: 230 | L11: 0.85 | M11: 0.95 | N11: =IF(I11="kVA",IF(J11="3Ph",(H11*1000/(1.732*M11*K11)),(H11*1000/(M11*K11))),IF(I11="kW",IF(J11="3Ph",(H11*1000/(1.732*M11*K11*L11)),(H11*1000/(M11*K11*L11))))) -> 0.80764571 | O11: =IF(G11="MOTOR",(6*N11),IF(G11="VFD",(1*N11),0)) -> 0 | P11: =IF(G11="MOTOR",0.2,"0.00") -> 0.00 | Q11: 65 | R11: 0 | S11: =(Q11*1000*SQRT(R11)/94) -> 0 | T11: AIR | U11: 3C | V11: 4 | W11: =CONCATENATE(U11," X ",V11) -> 3C X 4 | X11: =(IF(J11="1Ph",W11,IF(J11="3Ph",(IF(G11="MOTOR",(CONCATENATE(W11,"+PE")),W11))))) -> 3C X 4 | Y11: 0.6/1.0 | Z11: =IF(T11="AIR",VLOOKUP(W11,'Catalogue Aluminium'!$B$141:$G$173,2,FALSE),IF(T11="GROUND",VLOOKUP(W11,'Catalogue Aluminium'!$B$141:$G$173,3,FALSE),IF(T11="DUCT",VLOOKUP(W11,'Catalogue Aluminium'!$B$141:$G$173,4,FALSE),IF(T11="TRENCH",VLOOKUP(W11,'Catalogue Aluminium'!$B$141:$G$173,2,FALSE))))) -> 38 | AA11: =VLOOKUP(W11,'Catalogue Aluminium'!$B$141:$G$173,5,FALSE) -> 5.9 | AB11: =VLOOKUP(W11,'Catalogue Aluminium'!$B$141:$G$173,6,FALSE) -> 0.0947 | AC11: =37+30 -> 67 | AD11: =40+50+38+50+58+60+20+31+47 -> 394 | AE11: =11+8+3+10+10 -> 42 | AF11: =5+5 -> 10 | AG11: =ROUNDUP(SUM(AC11:AF11)*0.1,0) -> 52 | AH11: =CEILING(SUM(AC11:AG11),10) -> 570 | AI11: =IF(T11="AIR",'Catalogue Aluminium'!$K$141,IF(T11="TRENCH",'Catalogue Aluminium'!$K$144,"NA")) -> 0.82 | AJ11: =IF(T11="Air",(IF(U11="1C",'Catalogue Aluminium'!$L$141,'Catalogue Aluminium'!$M$141)),IF(T11="DUCT",(IF($U11="1C",'Catalogue Aluminium'!$L$142,'Catalogue Aluminium'!$M$142)),IF(T11="GROUND",(IF($U11="1C",'Catalogue Aluminium'!$L$143,'Catalogue Aluminium'!$M$143)),IF(T11="TRENCH",(IF($U11="1C",'Catalogue Aluminium'!$L$144,'Catalogue Aluminium'!$M$144)))))) -> 0.73 | AK11: =IF(T11="Air",'Catalogue Aluminium'!$N$141,IF(T11="GROUND",'Catalogue Aluminium'!$N$142,IF(T11="DUCT",'Catalogue Aluminium'!$N$143,IF(T11="TRENCH",'Catalogue Aluminium'!$N$144,"NA")))) -> NA | AL11: =IF(T11="Air",(IF(U11="1C",'Catalogue Aluminium'!$O$141,'Catalogue Aluminium'!$P$141)),IF(T11="DUCT",(IF($U11="1C",'Catalogue Aluminium'!$O$142,'Catalogue Aluminium'!$P$142)),IF(T11="GROUND",(IF($U11="1C",'Catalogue Aluminium'!$O$143,'Catalogue Aluminium'!$P$143)),IF(T11="TRENCH",(IF($U11="1C",'Catalogue Aluminium'!$O$144,'Catalogue Aluminium'!$P$144)))))) -> NA | AM11: =IF(T11="AIR","NA",IF(T11="TRENCH","NA",IF(T11="DUCT",IF(U11="1C",VLOOKUP(V11,'Catalogue Aluminium'!$Q$142:$S$153,2,FALSE),VLOOKUP(V11,'Catalogue Aluminium'!$Q$142:$S$153,3)),IF(T11="GROUND",IF(U11="1C",VLOOKUP(V11,'Catalogue Aluminium'!$Q$142:$S$153,2,FALSE),VLOOKUP(V11,'Catalogue Aluminium'!$Q$142:$S$153,3)))))) -> NA | AN11: =IF(T11="AIR",AI11*AJ11,IF(T11="TRENCH",AI11*AJ11,IF(T11="DUCT",AJ11*AK11*AL11*AM11,IF(T11="GROUND",AJ11*AK11*AL11*AM11)))) -> 0.5986 | AO11: =Z11*AN11 -> 22.7468 | AP11: =CEILING(((N11)/AO11),1) -> 1 | AQ11: =IF(AO11*AP11>=N11,"YES","NO") -> YES | AR11: =SQRT(3)*AH11*N11*((AA11*L11)+(AB11*SIN(ACOS(L11))))*100/(AP11*K11*1000) -> 1.7558938 | AS11: =IF(G11="INCOMER",(IF(AR11<=2,"YES","NO")),IF(G11="POWER",(IF(AR11<=2.5,"YES","NO")),IF(G11="MOTOR",(IF(AR11<=3,"YES","NO"))))) -> YES | AT11: =IF(G11="MOTOR",(SQRT(3)*AH11*O11*((AA11*P11)+(AB11*SIN(ACOS(P11))))*100/(AP11*K11*1000)),"NA") -> NA | AU11: =IF(G11="MOTOR",IF(AT11<=15,"YES","NO"),"NA") -> NA | AV11: =IF(U11="1C",CONCATENATE(AP11,"R x ",Y11,"kV x ",U11," x ",V11," Sqmm/Phase"),CONCATENATE(AP11,"R x ","6/10 (12)kV x ",U11," x ",V11," Sqmm")) -> 1R x 6/10 (12)kV x 3C x 4 Sqmm | AW11: =IF(U11="1C",CONCATENATE(AP11,"R x ",Y11,"kV x ",U11," x ",V11," Sqmm/Phase"),CONCATENATE(AP11,"R x ","6/10 (12)kV x ",U11," x ",V11," Sqmm")) -> 1R x 6/10 (12)kV x 3C x 4 Sqmm | AX11: =IF(U11="1C",(3*AH11*AP11),(AH11*AP11)) -> 570 | AZ11: =IF(U11="1C",(3*AP11*2),(AP11*2)) -> 2 | BA11: =CONCATENATE(IF(BE11=1,BE$4,""),IF(BF11=1,BF$4,""),IF(BG11=1,BG$4,""),IF(BH11=1,BH$4,""),IF(BI11=1,BI$4,""),IF(BJ11=1,BJ$4,""),IF(BK11=1,BK$4,""),IF(BL11=1,BL$4,""),IF(BM11=1,BM$4,""),IF(BN11=1,BN$4,""),IF(BO11=1,BO$4,""),IF(BP11=1,BP$4,""),IF(BQ11=1,BQ$4,""),IF(BR11=1,BR$4,""),IF(BS11=1,BS$4,""),IF(BT11=1,BT$4,""),IF(BU11=1,BU$4,""),IF(BV11=1,BV$4,""),IF(BW11=1,BW$4,""),IF(BX11=1,BX$4,""),IF(BY11=1,BY$4,""),IF(BZ11=1,BZ$4,""),IF(CA11=1,CA$4,""),IF(CB11=1,CB$4,""),IF(CC11=1,CC$4,""),IF(CD11=1,CD$4,""),IF(CE11=1,CE$4,""),IF(CF11=1,CF$4,""),IF(CG11=1,CG$4,""),IF(CH11=1,CH$4,""),IF(CI11=1,CI$4,""),IF(CJ11=1,CJ$4,""),IF(CK11=1,CK$4,""),IF(CL11=1,CL$4,""),IF(CM11=1,CM$4,""),IF(CN11=1,CN$4,""),IF(CO11=1,CO$4,""),IF(CP11=1,CP$4,""),IF(CQ11=1,CQ$4,""),IF(CR11=1,CR$4,""),IF(CS11=1,CS$4,""),IF(CT11=1,CT$4,""),IF(CU11=1,CU$4,""),IF(CV11=1,CV$4,""),IF(CW11=1,CW$4,""),IF(CX11=1,CX$4,""),IF(CY11=1,CY$4,""),IF(CZ11=1,CZ$4,""),IF(DA11=1,DA$4,""),IF(DB11=1,DB$4,""),IF(DC11=1,DC$4,""),IF(DD11=1,DD$4,""),IF(DE11=1,DE$4,""),IF(DF11=1,DF$4,""),IF(DG11=1,DG$4,""),IF(DH11=1,DH$4,""),IF(DI11=1,DI$4,""),IF(DJ11=1,DJ$4,""),IF(DK11=1,DK$4,""),IF(DL11=1,DL$4,""),IF(DM11=1,DM$4,""),IF(DN11=1,DN$4,""),IF(DO11=1,DO$4,""),IF(DP11=1,DP$4,""),IF(DQ11=1,DQ$4,""),IF(DR11=1,DR$4,""),IF(DS11=1,DS$4,""),IF(DT11=1,DT$4,""),IF(DU11=1,DU$4,"")) -> ACDEFGIJ | BB11: =VLOOKUP(W11,'Catalogue Aluminium'!$B$141:$H$173,7,FALSE) -> 15 | BC11: =AP11*BB11 -> 15 | BF11: 1 | BI11: 1 | BJ11: 1 | BN11: 1 | BV11: 1 | BW11: 1 | BZ11: 1 | CD11: 1 | DW11: =IF(BE11=1,($BC11*BE11),0) -> 0 | DX11: =IF(BF11=1,($BC11*BF11),0) -> 15 | DY11: =IF(BG11=1,($BC11*BG11),0) -> 0 | DZ11: =IF(BH11=1,($BC11*BH11),0) -> 0 | EA11: =IF(BI11=1,($BC11*BI11),0) -> 15 | EB11: =IF(BJ11=1,($BC11*BJ11),0) -> 15 | EC11: =IF(BK11=1,($BC11*BK11),0) -> 0 | ED11: =IF(BL11=1,($BC11*BL11),0) -> 0 | ... GM11: =IF(DU11=1,($BC11*DU11),0) -> 0
